Workbook

Sheet 施設別電力使用量
A1: 対象施設別電力使用量
A2: No. | B2: 対象施設名 | C2: 電力使用量（kWh） | D2: 備考
A3: 1 | B3: 古平町立古平小学校 | C3: ='1.古平町立古平小学校'!AY368*0.5 -> 588001
A4: 2 | B4: 古平町立古平中学校 | C4: ='2.古平町立古平中学校'!AY368*0.5 -> 97880
A5: 3 | B5: 古平町立診療所海のまちクリニック | C5: ='3.古平町立診療所海のまちクリニック'!AY368*0.5 -> 142623
A6: 4 | B6: 古平町温泉保養センター （日本海ふるびら温泉しおかぜ） | C6: ='4.古平町温泉保養センター'!AY368*0.5 -> 172999
A7: 5 | B7: 古平町高齢者総合支援センター （元気プラザ） | C7: 79163.8 | D7: デマンドデータは隣接する地域福祉センターとの合算値
A8: 6 | B8: 古平町B&G海洋センター | C8: ='7.古平町B&G海洋センター'!AY368*0.5 -> 65895
A9: 7 | B9: 古平町一般廃棄物最終処分場 （古平町クリーンセンター） | C9: ='8.古平町一般廃棄物最終処分場'!AZ368*0.5 -> 132851
A10: 8-1 | B10: 認定こども園 ふるびら幼児センターみらい（電灯） | C10: ='9-1.認定こども園ふるびら幼児センターみらい（電灯）'!AY368*0.5 -> 22022.2
A11: 8-2 | B11: 認定こども園 ふるびら幼児センターみらい（動力） | C11: ='9-2.認定こども園ふるびら幼児センターみらい（動力）'!AY368*0.5 -> 10378.9
A12: 8-3 | B12: 認定こども園 ふるびら幼児センターみらい（融雪） | C12: ='9-3.認定こども園ふるびら幼児センターみらい（融雪）'!AY368*0.5 -> 5650.9
C13: 集計期間（2024/8/1-2025/7/31）

Sheet 1.古平町立古平小学校
A1: 古平町立古平小学校
A2: 日付 | B2: 曜日 | C2: 0.020833333 | D2: 0.041666667 | E2: 0.0625 | F2: 0.083333333 | G2: 0.10416667 | H2: 0.125 | I2: 0.14583333 | J2: 0.16666667 | K2: 0.1875 | L2: 0.20833333 | M2: 0.22916667 | N2: 0.25 | O2: 0.27083333 | P2: 0.29166667 | Q2: 0.3125 | R2: 0.33333333 | S2: 0.35416667 | T2: 0.375 | U2: 0.39583333 | V2: 0.41666667 | W2: 0.4375 | X2: 0.45833333 | Y2: 0.47916667 | Z2: 0.5 | AA2: 0.52083333 | AB2: 0.54166667 | AC2: 0.5625 | AD2: 0.58333333 | AE2: 0.60416667 | AF2: 0.625 | AG2: 0.64583333 | AH2: 0.66666667 | AI2: 0.6875 | AJ2: 0.70833333 | AK2: 0.72916667 | AL2: 0.75 | AM2: 0.77083333 | AN2: 0.79166667 | AO2: 0.8125 | AP2: 0.83333333 | AQ2: 0.85416667 | AR2: 0.875 | AS2: 0.89583333 | AT2: 0.91666667 | AU2: 0.9375 | AV2: 0.95833333 | AW2: 0.97916667 | AX2: 0 | AY2: 日別合計
A3: 45505 | B3: 木曜日 | C3: 34 | D3: 34 | E3: 40 | F3: 88 | G3: 56 | H3: 14 | I3: 14 | J3: 16 | K3: 14 | L3: 14 | M3: 14 | N3: 14 | O3: 16 | P3: 16 | Q3: 20 | R3: 20 | S3: 22 | T3: 20 | U3: 22 | V3: 20 | W3: 20 | X3: 22 | Y3: 22 | Z3: 24 | AA3: 20 | AB3: 22 | AC3: 24 | AD3: 24 | AE3: 26 | AF3: 28 | AG3: 24 | AH3: 24 | AI3: 26 | AJ3: 18 | AK3: 20 | AL3: 20 | AM3: 16 | AN3: 14 | AO3: 18 | AP3: 16 | AQ3: 14 | AR3: 18 | AS3: 14 | AT3: 16 | AU3: 68 | AV3: 100 | AW3: 66 | AX3: 28 | AY3: =SUM(C3:AX3) -> 1260
A4: 45506 | B4: 金曜日 | C4: 14 | D4: 18 | E4: 14 | F4: 14 | G4: 16 | H4: 16 | I4: 14 | J4: 16 | K4: 18 | L4: 14 | M4: 16 | N4: 18 | O4: 16 | P4: 16 | Q4: 20 | R4: 22 | S4: 22 | T4: 20 | U4: 24 | V4: 28 | W4: 24 | X4: 28 | Y4: 24 | Z4: 26 | AA4: 24 | AB4: 24 | AC4: 22 | AD4: 34 | AE4: 34 | AF4: 30 | AG4: 32 | AH4: 38 | AI4: 40 | AJ4: 30 | AK4: 16 | AL4: 20 | AM4: 16 | AN4: 14 | AO4: 20 | AP4: 16 | AQ4: 18 | AR4: 16 | AS4: 14 | AT4: 20 | AU4: 70 | AV4: 100 | AW4: 62 | AX4: 28 | AY4: =SUM(C4:AX4) -> 1196
A5: 45507 | B5: 土曜日 | C5: 14 | D5: 18 | E5: 16 | F5: 16 | G5: 16 | H5: 18 | I5: 14 | J5: 20 | K5: 14 | L5: 16 | M5: 20 | N5: 16 | O5: 18 | P5: 16 | Q5: 16 | R5: 20 | S5: 16 | T5: 24 | U5: 24 | V5: 36 | W5: 34 | X5: 34 | Y5: 28 | Z5: 28 | AA5: 26 | AB5: 28 | AC5: 30 | AD5: 32 | AE5: 30 | AF5: 30 | AG5: 30 | AH5: 34 | AI5: 28 | AJ5: 22 | AK5: 14 | AL5: 16 | AM5: 20 | AN5: 16 | AO5: 18 | AP5: 16 | AQ5: 18 | AR5: 16 | AS5: 16 | AT5: 18 | AU5: 70 | AV5: 102 | AW5: 60 | AX5: 22 | AY5: =SUM(C5:AX5) -> 1204
A6: 45508 | B6: 日曜日 | C6: 16 | D6: 18 | E6: 16 | F6: 14 | G6: 18 | H6: 16 | I6: 14 | J6: 18 | K6: 16 | L6: 14 | M6: 20 | N6: 16 | O6: 18 | P6: 16 | Q6: 18 | R6: 16 | S6: 16 | T6: 16 | U6: 16 | V6: 16 | W6: 18 | X6: 16 | Y6: 18 | Z6: 16 | AA6: 14 | AB6: 18 | AC6: 16 | AD6: 16 | AE6: 16 | AF6: 16 | AG6: 16 | AH6: 18 | AI6: 16 | AJ6: 18 | AK6: 14 | AL6: 16 | AM6: 18 | AN6: 14 | AO6: 16 | AP6: 14 | AQ6: 16 | AR6: 16 | AS6: 14 | AT6: 14 | AU6: 70 | AV6: 98 | AW6: 64 | AX6: 24 | AY6: =SUM(C6:AX6) -> 968
A7: 45509 | B7: 月曜日 | C7: 14 | D7: 14 | E7: 14 | F7: 14 | G7: 16 | H7: 14 | I7: 14 | J7: 14 | K7: 14 | L7: 18 | M7: 14 | N7: 16 | O7: 16 | P7: 16 | Q7: 16 | R7: 20 | S7: 16 | T7: 20 | U7: 22 | V7: 18 | W7: 18 | X7: 22 | Y7: 18 | Z7: 18 | AA7: 20 | AB7: 18 | AC7: 22 | AD7: 24 | AE7: 18 | AF7: 22 | AG7: 24 | AH7: 22 | AI7: 22 | AJ7: 24 | AK7: 14 | AL7: 16 | AM7: 14 | AN7: 18 | AO7: 14 | AP7: 14 | AQ7: 14 | AR7: 16 | AS7: 16 | AT7: 14 | AU7: 68 | AV7: 98 | AW7: 60 | AX7: 24 | AY7: =SUM(C7:AX7) -> 1012
A8: 45510 | B8: 火曜日 | C8: 16 | D8: 16 | E8: 16 | F8: 14 | G8: 18 | H8: 14 | I8: 16 | J8: 14 | K8: 18 | L8: 16 | M8: 14 | N8: 18 | O8: 16 | P8: 18 | Q8: 18 | R8: 22 | S8: 20 | T8: 26 | U8: 24 | V8: 26 | W8: 32 | X8: 50 | Y8: 46 | Z8: 50 | AA8: 36 | AB8: 34 | AC8: 30 | AD8: 26 | AE8: 24 | AF8: 28 | AG8: 24 | AH8: 24 | AI8: 26 | AJ8: 22 | AK8: 18 | AL8: 20 | AM8: 18 | AN8: 18 | AO8: 16 | AP8: 18 | AQ8: 16 | AR8: 14 | AS8: 18 | AT8: 16 | AU8: 20 | AV8: 32 | AW8: 28 | AX8: 88 | AY8: =SUM(C8:AX8) -> 1152
A9: 45511 | B9: 水曜日 | C9: 86 | D9: 56 | E9: 14 | F9: 14 | G9: 14 | H9: 12 | I9: 18 | J9: 14 | K9: 14 | L9: 14 | M9: 16 | N9: 14 | O9: 14 | P9: 16 | Q9: 18 | R9: 18 | S9: 20 | T9: 20 | U9: 20 | V9: 24 | W9: 30 | X9: 52 | Y9: 44 | Z9: 46 | AA9: 36 | AB9: 30 | AC9: 32 | AD9: 26 | AE9: 24 | AF9: 24 | AG9: 26 | AH9: 24 | AI9: 32 | AJ9: 28 | AK9: 24 | AL9: 22 | AM9: 24 | AN9: 22 | AO9: 16 | AP9: 20 | AQ9: 16 | AR9: 18 | AS9: 18 | AT9: 18 | AU9: 68 | AV9: 104 | AW9: 64 | AX9: 30 | AY9: =SUM(C9:AX9) -> 1354
A10: 45512 | B10: 木曜日 | C10: 16 | D10: 18 | E10: 16 | F10: 16 | G10: 18 | H10: 16 | I10: 18 | J10: 16 | K10: 16 | L10: 18 | M10: 16 | N10: 20 | O10: 16 | P10: 20 | Q10: 18 | R10: 20 | S10: 22 | T10: 24 | U10: 22 | V10: 24 | W10: 20 | X10: 42 | Y10: 62 | Z10: 48 | AA10: 28 | AB10: 30 | AC10: 30 | AD10: 28 | AE10: 28 | AF10: 28 | AG10: 32 | AH10: 28 | AI10: 30 | AJ10: 24 | AK10: 22 | AL10: 16 | AM10: 16 | AN10: 20 | AO10: 16 | AP10: 18 | AQ10: 16 | AR10: 18 | AS10: 18 | AT10: 18 | AU10: 18 | AV10: 14 | AW10: 20 | AX10: 16 | AY10: =SUM(C10:AX10) -> 1074
A11: 45513 | B11: 金曜日 | C11: 18 | D11: 16 | E11: 18 | F11: 16 | G11: 16 | H11: 16 | I11: 18 | J11: 18 | K11: 16 | L11: 16 | M11: 18 | N11: 18 | O11: 18 | P11: 16 | Q11: 22 | R11: 20 | S11: 20 | T11: 22 | U11: 26 | V11: 24 | W11: 24 | X11: 30 | Y11: 28 | Z11: 30 | AA11: 28 | AB11: 28 | AC11: 28 | AD11: 28 | AE11: 28 | AF11: 30 | AG11: 42 | AH11: 46 | AI11: 60 | AJ11: 54 | AK11: 20 | AL11: 20 | AM11: 20 | AN11: 18 | AO11: 20 | AP11: 16 | AQ11: 18 | AR11: 16 | AS11: 20 | AT11: 16 | AU11: 20 | AV11: 36 | AW11: 38 | AX11: 38 | AY11: =SUM(C11:AX11) -> 1172
A12: 45514 | B12: 土曜日 | C12: 38 | D12: 38 | E12: 40 | F12: 36 | G12: 38 | H12: 38 | I12: 38 | J12: 44 | K12: 138 | L12: 140 | M12: 142 | N12: 142 | O12: 136 | P12: 142 | Q12: 144 | R12: 70 | S12: 16 | T12: 16 | U12: 20 | V12: 16 | W12: 18 | X12: 18 | Y12: 18 | Z12: 16 | AA12: 18 | AB12: 16 | AC12: 16 | AD12: 20 | AE12: 16 | AF12: 16 | AG12: 18 | AH12: 18 | AI12: 16 | AJ12: 20 | AK12: 16 | AL12: 16 | AM12: 18 | AN12: 16 | AO12: 18 | AP12: 18 | AQ12: 18 | AR12: 16 | AS12: 16 | AT12: 20 | AU12: 96 | AV12: 144 | AW12: 136 | AX12: 76 | AY12: =SUM(C12:AX12) -> 2300
A13: 45515 | B13: 日曜日 | C13: 40 | D13: 16 | E13: 18 | F13: 16 | G13: 18 | H13: 16 | I13: 16 | J13: 18 | K13: 16 | L13: 18 | M13: 16 | N13: 14 | O13: 14 | P13: 18 | Q13: 14 | R13: 16 | S13: 18 | T13: 18 | U13: 18 | V13: 18 | W13: 18 | X13: 16 | Y13: 18 | Z13: 14 | AA13: 16 | AB13: 18 | AC13: 14 | AD13: 16 | AE13: 18 | AF13: 14 | AG13: 16 | AH13: 18 | AI13: 16 | AJ13: 14 | AK13: 18 | AL13: 16 | AM13: 14 | AN13: 14 | AO13: 20 | AP13: 14 | AQ13: 14 | AR13: 18 | AS13: 16 | AT13: 14 | AU13: 70 | AV13: 98 | AW13: 70 | AX13: 36 | AY13: =SUM(C13:AX13) -> 1014
A14: 45516 | B14: 月曜日 | C14: 14 | D14: 18 | E14: 16 | F14: 18 | G14: 16 | H14: 16 | I14: 20 | J14: 14 | K14: 18 | L14: 16 | M14: 16 | N14: 18 | O14: 16 | P14: 18 | Q14: 16 | R14: 16 | S14: 20 | T14: 16 | U14: 20 | V14: 16 | W14: 18 | X14: 16 | Y14: 20 | Z14: 16 | AA14: 18 | AB14: 18 | AC14: 18 | AD14: 16 | AE14: 16 | AF14: 18 | AG14: 22 | AH14: 18 | AI14: 20 | AJ14: 18 | AK14: 20 | AL14: 20 | AM14: 18 | AN14: 18 | AO14: 16 | AP14: 16 | AQ14: 20 | AR14: 16 | AS14: 20 | AT14: 16 | AU14: 70 | AV14: 102 | AW14: 64 | AX14: 26 | AY14: =SUM(C14:AX14) -> 1032
... A367: 45869 | B367: 木曜日 | C367: 14 | D367: 16 | E367: 16 | F367: 14 | G367: 14 | H367: 16 | I367: 18 | J367: 14 | K367: 14 | L367: 14 | M367: 18 | N367: 14 | O367: 16 | P367: 18 | Q367: 18 | R367: 18 | S367: 22 | T367: 20 | U367: 24 | V367: 22 | W367: 38 | X367: 48 | Y367: 48 | Z367: 32 | AA367: 32 | AB367: 30 | AC367: 24 | AD367: 26 | AE367: 28 | AF367: 24 | AG367: 36 | AH367: 28 | AI367: 26 | AJ367: 22 | AK367: 20 | AL367: 14 | AM367: 16 | AN367: 14 | AO367: 16 | AP367: 16 | AQ367: 14 | AR367: 14 | AS367: 18 | AT367: 14 | AU367: 80 | AV367: 98 | AW367: 58 | AX367: 16 | AY367: =SUM(C367:AX367) -> 1190
AY368: =SUM(AY3:AY367) -> 1176002

Sheet 2.古平町立古平中学校
A1: 古平町立古平中学校
A2: 日付 | B2: 曜日 | C2: 0.020833333 | D2: 0.041666667 | E2: 0.0625 | F2: 0.083333333 | G2: 0.10416667 | H2: 0.125 | I2: 0.14583333 | J2: 0.16666667 | K2: 0.1875 | L2: 0.20833333 | M2: 0.22916667 | N2: 0.25 | O2: 0.27083333 | P2: 0.29166667 | Q2: 0.3125 | R2: 0.33333333 | S2: 0.35416667 | T2: 0.375 | U2: 0.39583333 | V2: 0.41666667 | W2: 0.4375 | X2: 0.45833333 | Y2: 0.47916667 | Z2: 0.5 | AA2: 0.52083333 | AB2: 0.54166667 | AC2: 0.5625 | AD2: 0.58333333 | AE2: 0.60416667 | AF2: 0.625 | AG2: 0.64583333 | AH2: 0.66666667 | AI2: 0.6875 | AJ2: 0.70833333 | AK2: 0.72916667 | AL2: 0.75 | AM2: 0.77083333 | AN2: 0.79166667 | AO2: 0.8125 | AP2: 0.83333333 | AQ2: 0.85416667 | AR2: 0.875 | AS2: 0.89583333 | AT2: 0.91666667 | AU2: 0.9375 | AV2: 0.95833333 | AW2: 0.97916667 | AX2: 0 | AY2: 日別合計
A3: 45505 | B3: 木曜日 | C3: 8 | D3: 8 | E3: 8 | F3: 10 | G3: 8 | H3: 8 | I3: 8 | J3: 8 | K3: 8 | L3: 8 | M3: 8 | N3: 8 | O3: 8 | P3: 8 | Q3: 12 | R3: 10 | S3: 12 | T3: 14 | U3: 12 | V3: 14 | W3: 16 | X3: 14 | Y3: 14 | Z3: 16 | AA3: 14 | AB3: 12 | AC3: 12 | AD3: 10 | AE3: 12 | AF3: 10 | AG3: 10 | AH3: 10 | AI3: 10 | AJ3: 10 | AK3: 8 | AL3: 8 | AM3: 8 | AN3: 8 | AO3: 10 | AP3: 8 | AQ3: 8 | AR3: 8 | AS3: 10 | AT3: 8 | AU3: 8 | AV3: 8 | AW3: 10 | AX3: 8 | AY3: =SUM(C3:AX3) -> 476
A4: 45506 | B4: 金曜日 | C4: 8 | D4: 8 | E4: 8 | F4: 8 | G4: 8 | H4: 10 | I4: 8 | J4: 8 | K4: 8 | L4: 8 | M4: 8 | N4: 8 | O4: 8 | P4: 8 | Q4: 12 | R4: 12 | S4: 14 | T4: 28 | U4: 30 | V4: 30 | W4: 32 | X4: 32 | Y4: 30 | Z4: 30 | AA4: 18 | AB4: 12 | AC4: 14 | AD4: 16 | AE4: 28 | AF4: 26 | AG4: 18 | AH4: 12 | AI4: 14 | AJ4: 12 | AK4: 8 | AL4: 8 | AM4: 8 | AN4: 8 | AO4: 8 | AP4: 8 | AQ4: 10 | AR4: 8 | AS4: 8 | AT4: 8 | AU4: 10 | AV4: 8 | AW4: 8 | AX4: 8 | AY4: =SUM(C4:AX4) -> 650
A5: 45507 | B5: 土曜日 | C5: 8 | D5: 10 | E5: 8 | F5: 8 | G5: 8 | H5: 8 | I5: 10 | J5: 8 | K5: 8 | L5: 8 | M5: 8 | N5: 8 | O5: 8 | P5: 8 | Q5: 6 | R5: 10 | S5: 8 | T5: 8 | U5: 10 | V5: 12 | W5: 10 | X5: 10 | Y5: 16 | Z5: 16 | AA5: 12 | AB5: 14 | AC5: 16 | AD5: 20 | AE5: 20 | AF5: 22 | AG5: 18 | AH5: 8 | AI5: 8 | AJ5: 8 | AK5: 8 | AL5: 10 | AM5: 6 | AN5: 10 | AO5: 8 | AP5: 10 | AQ5: 8 | AR5: 8 | AS5: 8 | AT5: 10 | AU5: 8 | AV5: 8 | AW5: 8 | AX5: 10 | AY5: =SUM(C5:AX5) -> 488
A6: 45508 | B6: 日曜日 | C6: 8 | D6: 8 | E6: 8 | F6: 8 | G6: 10 | H6: 8 | I6: 8 | J6: 8 | K6: 8 | L6: 8 | M6: 8 | N6: 8 | O6: 8 | P6: 8 | Q6: 8 | R6: 8 | S6: 8 | T6: 8 | U6: 10 | V6: 8 | W6: 10 | X6: 10 | Y6: 10 | Z6: 8 | AA6: 8 | AB6: 8 | AC6: 8 | AD6: 8 | AE6: 8 | AF6: 8 | AG6: 8 | AH6: 8 | AI6: 8 | AJ6: 8 | AK6: 6 | AL6: 8 | AM6: 8 | AN6: 8 | AO6: 8 | AP6: 10 | AQ6: 8 | AR6: 8 | AS6: 8 | AT6: 8 | AU6: 8 | AV6: 10 | AW6: 8 | AX6: 8 | AY6: =SUM(C6:AX6) -> 396
A7: 45509 | B7: 月曜日 | C7: 8 | D7: 8 | E7: 8 | F7: 8 | G7: 8 | H7: 8 | I7: 8 | J7: 10 | K7: 8 | L7: 6 | M7: 8 | N7: 8 | O7: 8 | P7: 8 | Q7: 12 | R7: 12 | S7: 12 | T7: 20 | U7: 24 | V7: 24 | W7: 24 | X7: 24 | Y7: 24 | Z7: 22 | AA7: 12 | AB7: 12 | AC7: 12 | AD7: 12 | AE7: 14 | AF7: 12 | AG7: 12 | AH7: 12 | AI7: 12 | AJ7: 10 | AK7: 8 | AL7: 8 | AM7: 8 | AN7: 8 | AO7: 8 | AP7: 8 | AQ7: 8 | AR7: 10 | AS7: 8 | AT7: 8 | AU7: 8 | AV7: 8 | AW7: 8 | AX7: 8 | AY7: =SUM(C7:AX7) -> 544
A8: 45510 | B8: 火曜日 | C8: 8 | D8: 8 | E8: 8 | F8: 8 | G8: 8 | H8: 8 | I8: 8 | J8: 8 | K8: 10 | L8: 6 | M8: 8 | N8: 8 | O8: 6 | P8: 8 | Q8: 10 | R8: 12 | S8: 10 | T8: 12 | U8: 10 | V8: 12 | W8: 10 | X8: 10 | Y8: 10 | Z8: 12 | AA8: 10 | AB8: 10 | AC8: 8 | AD8: 8 | AE8: 10 | AF8: 10 | AG8: 10 | AH8: 10 | AI8: 10 | AJ8: 8 | AK8: 8 | AL8: 8 | AM8: 8 | AN8: 8 | AO8: 10 | AP8: 8 | AQ8: 8 | AR8: 8 | AS8: 8 | AT8: 10 | AU8: 8 | AV8: 8 | AW8: 8 | AX8: 10 | AY8: =SUM(C8:AX8) -> 430
A9: 45511 | B9: 水曜日 | C9: 8 | D9: 8 | E9: 8 | F9: 8 | G9: 8 | H9: 10 | I9: 8 | J9: 8 | K9: 8 | L9: 8 | M9: 8 | N9: 8 | O9: 8 | P9: 8 | Q9: 10 | R9: 12 | S9: 10 | T9: 16 | U9: 14 | V9: 14 | W9: 12 | X9: 12 | Y9: 10 | Z9: 12 | AA9: 10 | AB9: 12 | AC9: 12 | AD9: 10 | AE9: 12 | AF9: 12 | AG9: 12 | AH9: 12 | AI9: 12 | AJ9: 10 | AK9: 8 | AL9: 8 | AM9: 10 | AN9: 8 | AO9: 8 | AP9: 8 | AQ9: 10 | AR9: 8 | AS9: 8 | AT9: 8 | AU9: 8 | AV9: 10 | AW9: 8 | AX9: 8 | AY9: =SUM(C9:AX9) -> 468
A10: 45512 | B10: 木曜日 | C10: 8 | D10: 8 | E10: 10 | F10: 8 | G10: 8 | H10: 8 | I10: 8 | J10: 8 | K10: 10 | L10: 8 | M10: 6 | N10: 10 | O10: 6 | P10: 8 | Q10: 12 | R10: 12 | S10: 14 | T10: 28 | U10: 28 | V10: 28 | W10: 26 | X10: 30 | Y10: 24 | Z10: 24 | AA10: 14 | AB10: 12 | AC10: 14 | AD10: 14 | AE10: 14 | AF10: 12 | AG10: 14 | AH10: 12 | AI10: 12 | AJ10: 10 | AK10: 8 | AL10: 8 | AM10: 10 | AN10: 8 | AO10: 8 | AP10: 8 | AQ10: 10 | AR10: 8 | AS10: 8 | AT10: 8 | AU10: 8 | AV10: 10 | AW10: 8 | AX10: 8 | AY10: =SUM(C10:AX10) -> 586
A11: 45513 | B11: 金曜日 | C11: 8 | D11: 10 | E11: 8 | F11: 8 | G11: 8 | H11: 8 | I11: 8 | J11: 8 | K11: 10 | L11: 8 | M11: 6 | N11: 8 | O11: 8 | P11: 8 | Q11: 12 | R11: 14 | S11: 20 | T11: 24 | U11: 26 | V11: 24 | W11: 24 | X11: 24 | Y11: 24 | Z11: 24 | AA11: 14 | AB11: 12 | AC11: 16 | AD11: 14 | AE11: 16 | AF11: 12 | AG11: 14 | AH11: 14 | AI11: 12 | AJ11: 10 | AK11: 8 | AL11: 8 | AM11: 8 | AN11: 8 | AO11: 10 | AP11: 8 | AQ11: 8 | AR11: 8 | AS11: 10 | AT11: 8 | AU11: 8 | AV11: 8 | AW11: 8 | AX11: 10 | AY11: =SUM(C11:AX11) -> 582
A12: 45514 | B12: 土曜日 | C12: 8 | D12: 8 | E12: 8 | F12: 10 | G12: 8 | H12: 8 | I12: 8 | J12: 8 | K12: 8 | L12: 8 | M12: 8 | N12: 8 | O12: 8 | P12: 8 | Q12: 8 | R12: 8 | S12: 8 | T12: 6 | U12: 10 | V12: 6 | W12: 8 | X12: 8 | Y12: 8 | Z12: 8 | AA12: 8 | AB12: 8 | AC12: 8 | AD12: 8 | AE12: 8 | AF12: 8 | AG12: 8 | AH12: 8 | AI12: 8 | AJ12: 8 | AK12: 8 | AL12: 8 | AM12: 8 | AN12: 8 | AO12: 8 | AP12: 8 | AQ12: 10 | AR12: 8 | AS12: 8 | AT12: 8 | AU12: 10 | AV12: 8 | AW12: 8 | AX12: 8 | AY12: =SUM(C12:AX12) -> 388
A13: 45515 | B13: 日曜日 | C13: 8 | D13: 8 | E13: 10 | F13: 8 | G13: 8 | H13: 8 | I13: 8 | J13: 8 | K13: 10 | L13: 6 | M13: 8 | N13: 8 | O13: 8 | P13: 8 | Q13: 8 | R13: 8 | S13: 8 | T13: 8 | U13: 8 | V13: 8 | W13: 8 | X13: 8 | Y13: 8 | Z13: 8 | AA13: 8 | AB13: 8 | AC13: 8 | AD13: 8 | AE13: 8 | AF13: 8 | AG13: 8 | AH13: 8 | AI13: 8 | AJ13: 8 | AK13: 8 | AL13: 8 | AM13: 6 | AN13: 10 | AO13: 8 | AP13: 8 | AQ13: 8 | AR13: 10 | AS13: 8 | AT13: 8 | AU13: 8 | AV13: 8 | AW13: 8 | AX13: 10 | AY13: =SUM(C13:AX13) -> 390
A14: 45516 | B14: 月曜日 | C14: 8 | D14: 8 | E14: 8 | F14: 8 | G14: 8 | H14: 10 | I14: 8 | J14: 8 | K14: 8 | L14: 8 | M14: 8 | N14: 8 | O14: 8 | P14: 8 | Q14: 8 | R14: 8 | S14: 8 | T14: 8 | U14: 8 | V14: 8 | W14: 8 | X14: 8 | Y14: 8 | Z14: 8 | AA14: 8 | AB14: 8 | AC14: 8 | AD14: 8 | AE14: 8 | AF14: 8 | AG14: 6 | AH14: 8 | AI14: 8 | AJ14: 8 | AK14: 8 | AL14: 8 | AM14: 8 | AN14: 8 | AO14: 10 | AP14: 8 | AQ14: 8 | AR14: 8 | AS14: 10 | AT14: 8 | AU14: 8 | AV14: 8 | AW14: 10 | AX14: 8 | AY14: =SUM(C14:AX14) -> 390
... A367: 45869 | B367: 木曜日 | C367: 6 | D367: 6 | E367: 6 | F367: 6 | G367: 6 | H367: 6 | I367: 8 | J367: 6 | K367: 6 | L367: 6 | M367: 6 | N367: 12 | O367: 14 | P367: 12 | Q367: 12 | R367: 14 | S367: 12 | T367: 14 | U367: 14 | V367: 12 | W367: 14 | X367: 12 | Y367: 14 | Z367: 12 | AA367: 16 | AB367: 14 | AC367: 22 | AD367: 22 | AE367: 20 | AF367: 18 | AG367: 16 | AH367: 16 | AI367: 14 | AJ367: 12 | AK367: 8 | AL367: 8 | AM367: 10 | AN367: 8 | AO367: 6 | AP367: 6 | AQ367: 8 | AR367: 6 | AS367: 6 | AT367: 6 | AU367: 8 | AV367: 6 | AW367: 6 | AX367: 6 | AY367: =SUM(C367:AX367) -> 504
AY368: =SUM(AY3:AY367) -> 195760

Sheet 3.古平町立診療所海のまちクリニック
A1: 古平町立診療所海のまちクリニック
A2: 日付 | B2: 曜日 | C2: 0.020833333 | D2: 0.041666667 | E2: 0.0625 | F2: 0.083333333 | G2: 0.10416667 | H2: 0.125 | I2: 0.14583333 | J2: 0.16666667 | K2: 0.1875 | L2: 0.20833333 | M2: 0.22916667 | N2: 0.25 | O2: 0.27083333 | P2: 0.29166667 | Q2: 0.3125 | R2: 0.33333333 | S2: 0.35416667 | T2: 0.375 | U2: 0.39583333 | V2: 0.41666667 | W2: 0.4375 | X2: 0.45833333 | Y2: 0.47916667 | Z2: 0.5 | AA2: 0.52083333 | AB2: 0.54166667 | AC2: 0.5625 | AD2: 0.58333333 | AE2: 0.60416667 | AF2: 0.625 | AG2: 0.64583333 | AH2: 0.66666667 | AI2: 0.6875 | AJ2: 0.70833333 | AK2: 0.72916667 | AL2: 0.75 | AM2: 0.77083333 | AN2: 0.79166667 | AO2: 0.8125 | AP2: 0.83333333 | AQ2: 0.85416667 | AR2: 0.875 | AS2: 0.89583333 | AT2: 0.91666667 | AU2: 0.9375 | AV2: 0.95833333 | AW2: 0.97916667 | AX2: 0 | AY2: 日別合計
A3: 45505 | B3: 木曜日 | C3: 8 | D3: 8 | E3: 8 | F3: 8 | G3: 8 | H3: 10 | I3: 8 | J3: 8 | K3: 8 | L3: 8 | M3: 10 | N3: 10 | O3: 14 | P3: 16 | Q3: 20 | R3: 20 | S3: 22 | T3: 20 | U3: 28 | V3: 28 | W3: 26 | X3: 24 | Y3: 24 | Z3: 24 | AA3: 24 | AB3: 20 | AC3: 24 | AD3: 22 | AE3: 24 | AF3: 20 | AG3: 20 | AH3: 20 | AI3: 20 | AJ3: 18 | AK3: 16 | AL3: 16 | AM3: 12 | AN3: 10 | AO3: 10 | AP3: 8 | AQ3: 10 | AR3: 8 | AS3: 8 | AT3: 8 | AU3: 8 | AV3: 8 | AW3: 8 | AX3: 8 | AY3: =SUM(C3:AX3) -> 718
A4: 45506 | B4: 金曜日 | C4: 8 | D4: 8 | E4: 8 | F4: 8 | G4: 8 | H4: 8 | I4: 8 | J4: 8 | K4: 8 | L4: 8 | M4: 10 | N4: 12 | O4: 16 | P4: 14 | Q4: 22 | R4: 20 | S4: 28 | T4: 26 | U4: 24 | V4: 30 | W4: 32 | X4: 32 | Y4: 32 | Z4: 28 | AA4: 30 | AB4: 24 | AC4: 24 | AD4: 28 | AE4: 28 | AF4: 28 | AG4: 30 | AH4: 28 | AI4: 22 | AJ4: 24 | AK4: 18 | AL4: 18 | AM4: 14 | AN4: 14 | AO4: 18 | AP4: 12 | AQ4: 12 | AR4: 14 | AS4: 12 | AT4: 16 | AU4: 10 | AV4: 10 | AW4: 12 | AX4: 12 | AY4: =SUM(C4:AX4) -> 864
A5: 45507 | B5: 土曜日 | C5: 12 | D5: 10 | E5: 12 | F5: 10 | G5: 12 | H5: 10 | I5: 10 | J5: 12 | K5: 10 | L5: 14 | M5: 14 | N5: 18 | O5: 20 | P5: 16 | Q5: 20 | R5: 22 | S5: 28 | T5: 26 | U5: 24 | V5: 30 | W5: 22 | X5: 26 | Y5: 24 | Z5: 30 | AA5: 18 | AB5: 22 | AC5: 24 | AD5: 20 | AE5: 22 | AF5: 20 | AG5: 24 | AH5: 20 | AI5: 16 | AJ5: 24 | AK5: 22 | AL5: 20 | AM5: 22 | AN5: 14 | AO5: 18 | AP5: 16 | AQ5: 16 | AR5: 10 | AS5: 10 | AT5: 6 | AU5: 8 | AV5: 8 | AW5: 8 | AX5: 8 | AY5: =SUM(C5:AX5) -> 828
A6: 45508 | B6: 日曜日 | C6: 8 | D6: 8 | E6: 6 | F6: 8 | G6: 6 | H6: 8 | I6: 8 | J6: 6 | K6: 8 | L6: 6 | M6: 10 | N6: 10 | O6: 10 | P6: 10 | Q6: 12 | R6: 12 | S6: 12 | T6: 12 | U6: 12 | V6: 12 | W6: 12 | X6: 12 | Y6: 12 | Z6: 12 | AA6: 10 | AB6: 12 | AC6: 10 | AD6: 10 | AE6: 12 | AF6: 10 | AG6: 10 | AH6: 12 | AI6: 10 | AJ6: 8 | AK6: 12 | AL6: 10 | AM6: 10 | AN6: 8 | AO6: 10 | AP6: 8 | AQ6: 8 | AR6: 10 | AS6: 6 | AT6: 8 | AU6: 8 | AV6: 8 | AW6: 8 | AX6: 8 | AY6: =SUM(C6:AX6) -> 458
A7: 45509 | B7: 月曜日 | C7: 8 | D7: 8 | E7: 6 | F7: 8 | G7: 8 | H7: 8 | I7: 8 | J7: 8 | K7: 6 | L7: 8 | M7: 8 | N7: 10 | O7: 12 | P7: 12 | Q7: 16 | R7: 14 | S7: 16 | T7: 18 | U7: 18 | V7: 20 | W7: 18 | X7: 20 | Y7: 22 | Z7: 22 | AA7: 18 | AB7: 18 | AC7: 18 | AD7: 20 | AE7: 22 | AF7: 18 | AG7: 20 | AH7: 18 | AI7: 16 | AJ7: 14 | AK7: 14 | AL7: 14 | AM7: 12 | AN7: 12 | AO7: 8 | AP7: 12 | AQ7: 10 | AR7: 8 | AS7: 12 | AT7: 8 | AU7: 8 | AV7: 8 | AW7: 10 | AX7: 8 | AY7: =SUM(C7:AX7) -> 628
A8: 45510 | B8: 火曜日 | C8: 6 | D8: 10 | E8: 8 | F8: 8 | G8: 8 | H8: 8 | I8: 8 | J8: 8 | K8: 8 | L8: 8 | M8: 8 | N8: 12 | O8: 12 | P8: 14 | Q8: 16 | R8: 18 | S8: 18 | T8: 18 | U8: 24 | V8: 24 | W8: 26 | X8: 28 | Y8: 26 | Z8: 24 | AA8: 24 | AB8: 22 | AC8: 22 | AD8: 24 | AE8: 26 | AF8: 24 | AG8: 22 | AH8: 22 | AI8: 22 | AJ8: 20 | AK8: 16 | AL8: 14 | AM8: 14 | AN8: 14 | AO8: 12 | AP8: 12 | AQ8: 10 | AR8: 10 | AS8: 10 | AT8: 10 | AU8: 10 | AV8: 10 | AW8: 8 | AX8: 10 | AY8: =SUM(C8:AX8) -> 736
A9: 45511 | B9: 水曜日 | C9: 8 | D9: 8 | E9: 8 | F9: 10 | G9: 8 | H9: 8 | I9: 8 | J9: 8 | K9: 8 | L9: 10 | M9: 8 | N9: 10 | O9: 12 | P9: 12 | Q9: 24 | R9: 30 | S9: 24 | T9: 30 | U9: 30 | V9: 30 | W9: 26 | X9: 28 | Y9: 24 | Z9: 26 | AA9: 24 | AB9: 26 | AC9: 24 | AD9: 22 | AE9: 26 | AF9: 26 | AG9: 24 | AH9: 24 | AI9: 24 | AJ9: 20 | AK9: 18 | AL9: 14 | AM9: 16 | AN9: 16 | AO9: 16 | AP9: 14 | AQ9: 18 | AR9: 12 | AS9: 12 | AT9: 10 | AU9: 10 | AV9: 10 | AW9: 8 | AX9: 8 | AY9: =SUM(C9:AX9) -> 820
A10: 45512 | B10: 木曜日 | C10: 8 | D10: 8 | E10: 10 | F10: 8 | G10: 8 | H10: 8 | I10: 8 | J10: 8 | K10: 8 | L10: 8 | M10: 8 | N10: 12 | O10: 12 | P10: 14 | Q10: 20 | R10: 16 | S10: 20 | T10: 24 | U10: 32 | V10: 34 | W10: 34 | X10: 32 | Y10: 34 | Z10: 32 | AA10: 30 | AB10: 32 | AC10: 30 | AD10: 36 | AE10: 38 | AF10: 38 | AG10: 36 | AH10: 30 | AI10: 24 | AJ10: 22 | AK10: 18 | AL10: 20 | AM10: 16 | AN10: 12 | AO10: 12 | AP10: 8 | AQ10: 10 | AR10: 10 | AS10: 10 | AT10: 8 | AU10: 10 | AV10: 10 | AW10: 6 | AX10: 8 | AY10: =SUM(C10:AX10) -> 880
A11: 45513 | B11: 金曜日 | C11: 10 | D11: 8 | E11: 10 | F11: 10 | G11: 8 | H11: 8 | I11: 10 | J11: 8 | K11: 10 | L11: 10 | M11: 14 | N11: 18 | O11: 14 | P11: 16 | Q11: 24 | R11: 26 | S11: 24 | T11: 22 | U11: 30 | V11: 30 | W11: 26 | X11: 32 | Y11: 28 | Z11: 28 | AA11: 30 | AB11: 28 | AC11: 28 | AD11: 30 | AE11: 32 | AF11: 28 | AG11: 30 | AH11: 28 | AI11: 26 | AJ11: 28 | AK11: 24 | AL11: 24 | AM11: 18 | AN11: 20 | AO11: 14 | AP11: 14 | AQ11: 14 | AR11: 14 | AS11: 14 | AT11: 12 | AU11: 14 | AV11: 14 | AW11: 12 | AX11: 10 | AY11: =SUM(C11:AX11) -> 930
A12: 45514 | B12: 土曜日 | C12: 12 | D12: 12 | E12: 12 | F12: 12 | G12: 12 | H12: 12 | I12: 12 | J12: 12 | K12: 12 | L12: 12 | M12: 12 | N12: 18 | O12: 16 | P12: 18 | Q12: 18 | R12: 18 | S12: 18 | T12: 16 | U12: 18 | V12: 16 | W12: 18 | X12: 18 | Y12: 16 | Z12: 18 | AA12: 18 | AB12: 16 | AC12: 18 | AD12: 20 | AE12: 18 | AF12: 14 | AG12: 18 | AH12: 18 | AI12: 16 | AJ12: 12 | AK12: 14 | AL12: 14 | AM12: 14 | AN12: 12 | AO12: 12 | AP12: 8 | AQ12: 10 | AR12: 6 | AS12: 8 | AT12: 10 | AU12: 6 | AV12: 8 | AW12: 6 | AX12: 10 | AY12: =SUM(C12:AX12) -> 664
A13: 45515 | B13: 日曜日 | C13: 6 | D13: 8 | E13: 6 | F13: 8 | G13: 8 | H13: 8 | I13: 6 | J13: 8 | K13: 8 | L13: 8 | M13: 8 | N13: 10 | O13: 12 | P13: 10 | Q13: 12 | R13: 12 | S13: 18 | T13: 22 | U13: 24 | V13: 24 | W13: 20 | X13: 24 | Y13: 20 | Z13: 18 | AA13: 20 | AB13: 18 | AC13: 20 | AD13: 16 | AE13: 22 | AF13: 16 | AG13: 22 | AH13: 16 | AI13: 18 | AJ13: 18 | AK13: 18 | AL13: 16 | AM13: 14 | AN13: 16 | AO13: 12 | AP13: 10 | AQ13: 10 | AR13: 12 | AS13: 10 | AT13: 8 | AU13: 12 | AV13: 10 | AW13: 10 | AX13: 8 | AY13: =SUM(C13:AX13) -> 660
A14: 45516 | B14: 月曜日 | C14: 8 | D14: 10 | E14: 10 | F14: 8 | G14: 8 | H14: 6 | I14: 10 | J14: 6 | K14: 8 | L14: 8 | M14: 10 | N14: 14 | O14: 20 | P14: 20 | Q14: 18 | R14: 22 | S14: 20 | T14: 22 | U14: 24 | V14: 28 | W14: 24 | X14: 26 | Y14: 22 | Z14: 20 | AA14: 22 | AB14: 20 | AC14: 20 | AD14: 22 | AE14: 22 | AF14: 22 | AG14: 24 | AH14: 22 | AI14: 20 | AJ14: 16 | AK14: 16 | AL14: 16 | AM14: 18 | AN14: 16 | AO14: 18 | AP14: 14 | AQ14: 16 | AR14: 12 | AS14: 18 | AT14: 12 | AU14: 14 | AV14: 16 | AW14: 12 | AX14: 14 | AY14: =SUM(C14:AX14) -> 794
... A367: 45869 | B367: 木曜日 | C367: 12 | D367: 12 | E367: 12 | F367: 12 | G367: 8 | H367: 10 | I367: 10 | J367: 10 | K367: 10 | L367: 8 | M367: 12 | N367: 10 | O367: 14 | P367: 22 | Q367: 22 | R367: 24 | S367: 28 | T367: 32 | U367: 36 | V367: 38 | W367: 38 | X367: 36 | Y367: 36 | Z367: 36 | AA367: 36 | AB367: 32 | AC367: 34 | AD367: 36 | AE367: 38 | AF367: 34 | AG367: 36 | AH367: 28 | AI367: 32 | AJ367: 30 | AK367: 24 | AL367: 22 | AM367: 22 | AN367: 20 | AO367: 18 | AP367: 18 | AQ367: 16 | AR367: 16 | AS367: 16 | AT367: 16 | AU367: 14 | AV367: 14 | AW367: 16 | AX367: 12 | AY367: =SUM(C367:AX367) -> 1068
AY368: =SUM(AY3:AY367) -> 285246

Sheet 5.古平町高齢者総合支援センター
A1: 古平町高齢者総合支援センター（元気プラザ）
A2: 日付 | B2: 曜日 | C2: 0.020833333 | D2: 0.041666667 | E2: 0.0625 | F2: 0.083333333 | G2: 0.10416667 | H2: 0.125 | I2: 0.14583333 | J2: 0.16666667 | K2: 0.1875 | L2: 0.20833333 | M2: 0.22916667 | N2: 0.25 | O2: 0.27083333 | P2: 0.29166667 | Q2: 0.3125 | R2: 0.33333333 | S2: 0.35416667 | T2: 0.375 | U2: 0.39583333 | V2: 0.41666667 | W2: 0.4375 | X2: 0.45833333 | Y2: 0.47916667 | Z2: 0.5 | AA2: 0.52083333 | AB2: 0.54166667 | AC2: 0.5625 | AD2: 0.58333333 | AE2: 0.60416667 | AF2: 0.625 | AG2: 0.64583333 | AH2: 0.66666667 | AI2: 0.6875 | AJ2: 0.70833333 | AK2: 0.72916667 | AL2: 0.75 | AM2: 0.77083333 | AN2: 0.79166667 | AO2: 0.8125 | AP2: 0.83333333 | AQ2: 0.85416667 | AR2: 0.875 | AS2: 0.89583333 | AT2: 0.91666667 | AU2: 0.9375 | AV2: 0.95833333 | AW2: 0.97916667 | AX2: 0 | AY2: 日別合計
A3: 45505 | B3: 木曜日 | C3: 10 | D3: 8 | E3: 8 | F3: 10 | G3: 8 | H3: 8 | I3: 10 | J3: 8 | K3: 8 | L3: 8 | M3: 10 | N3: 8 | O3: 8 | P3: 10 | Q3: 10 | R3: 12 | S3: 14 | T3: 16 | U3: 16 | V3: 20 | W3: 22 | X3: 22 | Y3: 22 | Z3: 22 | AA3: 20 | AB3: 20 | AC3: 20 | AD3: 20 | AE3: 22 | AF3: 18 | AG3: 18 | AH3: 18 | AI3: 16 | AJ3: 18 | AK3: 16 | AL3: 12 | AM3: 14 | AN3: 12 | AO3: 12 | AP3: 12 | AQ3: 10 | AR3: 12 | AS3: 10 | AT3: 8 | AU3: 10 | AV3: 8 | AW3: 10 | AX3: 8 | AY3: =SUM(C3:AX3) -> 642
A4: 45506 | B4: 金曜日 | C4: 10 | D4: 8 | E4: 10 | F4: 10 | G4: 8 | H4: 10 | I4: 8 | J4: 8 | K4: 10 | L4: 8 | M4: 10 | N4: 8 | O4: 8 | P4: 10 | Q4: 10 | R4: 12 | S4: 18 | T4: 20 | U4: 22 | V4: 26 | W4: 24 | X4: 24 | Y4: 26 | Z4: 28 | AA4: 28 | AB4: 28 | AC4: 24 | AD4: 26 | AE4: 22 | AF4: 22 | AG4: 22 | AH4: 20 | AI4: 20 | AJ4: 22 | AK4: 22 | AL4: 12 | AM4: 12 | AN4: 12 | AO4: 12 | AP4: 10 | AQ4: 12 | AR4: 10 | AS4: 10 | AT4: 8 | AU4: 8 | AV4: 8 | AW4: 8 | AX4: 8 | AY4: =SUM(C4:AX4) -> 722
A5: 45507 | B5: 土曜日 | C5: 8 | D5: 8 | E5: 8 | F5: 6 | G5: 8 | H5: 8 | I5: 6 | J5: 8 | K5: 6 | L5: 8 | M5: 8 | N5: 8 | O5: 8 | P5: 10 | Q5: 8 | R5: 10 | S5: 10 | T5: 10 | U5: 12 | V5: 18 | W5: 18 | X5: 20 | Y5: 18 | Z5: 20 | AA5: 20 | AB5: 20 | AC5: 20 | AD5: 18 | AE5: 18 | AF5: 12 | AG5: 14 | AH5: 14 | AI5: 12 | AJ5: 14 | AK5: 14 | AL5: 16 | AM5: 16 | AN5: 16 | AO5: 16 | AP5: 14 | AQ5: 14 | AR5: 14 | AS5: 14 | AT5: 12 | AU5: 14 | AV5: 12 | AW5: 12 | AX5: 12 | AY5: =SUM(C5:AX5) -> 610
A6: 45508 | B6: 日曜日 | C6: 12 | D6: 12 | E6: 12 | F6: 10 | G6: 12 | H6: 12 | I6: 10 | J6: 12 | K6: 12 | L6: 10 | M6: 12 | N6: 10 | O6: 8 | P6: 10 | Q6: 8 | R6: 8 | S6: 10 | T6: 8 | U6: 8 | V6: 8 | W6: 8 | X6: 10 | Y6: 8 | Z6: 12 | AA6: 12 | AB6: 12 | AC6: 10 | AD6: 10 | AE6: 12 | AF6: 8 | AG6: 10 | AH6: 8 | AI6: 10 | AJ6: 10 | AK6: 8 | AL6: 12 | AM6: 8 | AN6: 12 | AO6: 10 | AP6: 12 | AQ6: 10 | AR6: 10 | AS6: 12 | AT6: 10 | AU6: 8 | AV6: 10 | AW6: 10 | AX6: 8 | AY6: =SUM(C6:AX6) -> 484
A7: 45509 | B7: 月曜日 | C7: 10 | D7: 8 | E7: 8 | F7: 10 | G7: 8 | H7: 8 | I7: 10 | J7: 8 | K7: 8 | L7: 8 | M7: 10 | N7: 8 | O7: 10 | P7: 8 | Q7: 10 | R7: 12 | S7: 14 | T7: 16 | U7: 20 | V7: 18 | W7: 20 | X7: 22 | Y7: 22 | Z7: 20 | AA7: 20 | AB7: 20 | AC7: 18 | AD7: 20 | AE7: 20 | AF7: 18 | AG7: 16 | AH7: 16 | AI7: 16 | AJ7: 16 | AK7: 16 | AL7: 12 | AM7: 12 | AN7: 12 | AO7: 10 | AP7: 12 | AQ7: 10 | AR7: 12 | AS7: 10 | AT7: 8 | AU7: 10 | AV7: 10 | AW7: 8 | AX7: 10 | AY7: =SUM(C7:AX7) -> 628
A8: 45510 | B8: 火曜日 | C8: 10 | D8: 8 | E8: 8 | F8: 8 | G8: 10 | H8: 8 | I8: 8 | J8: 10 | K8: 8 | L8: 8 | M8: 10 | N8: 8 | O8: 10 | P8: 8 | Q8: 10 | R8: 12 | S8: 16 | T8: 16 | U8: 14 | V8: 18 | W8: 18 | X8: 16 | Y8: 18 | Z8: 18 | AA8: 18 | AB8: 18 | AC8: 18 | AD8: 18 | AE8: 20 | AF8: 18 | AG8: 18 | AH8: 18 | AI8: 18 | AJ8: 16 | AK8: 16 | AL8: 14 | AM8: 12 | AN8: 12 | AO8: 12 | AP8: 12 | AQ8: 10 | AR8: 12 | AS8: 10 | AT8: 10 | AU8: 8 | AV8: 10 | AW8: 8 | AX8: 10 | AY8: =SUM(C8:AX8) -> 614
A9: 45511 | B9: 水曜日 | C9: 8 | D9: 8 | E9: 10 | F9: 8 | G9: 10 | H9: 10 | I9: 8 | J9: 8 | K9: 10 | L9: 8 | M9: 8 | N9: 10 | O9: 8 | P9: 10 | Q9: 10 | R9: 12 | S9: 14 | T9: 18 | U9: 20 | V9: 20 | W9: 24 | X9: 24 | Y9: 22 | Z9: 22 | AA9: 28 | AB9: 28 | AC9: 24 | AD9: 26 | AE9: 24 | AF9: 22 | AG9: 22 | AH9: 22 | AI9: 18 | AJ9: 20 | AK9: 20 | AL9: 12 | AM9: 14 | AN9: 12 | AO9: 12 | AP9: 12 | AQ9: 12 | AR9: 10 | AS9: 10 | AT9: 12 | AU9: 10 | AV9: 10 | AW9: 10 | AX9: 8 | AY9: =SUM(C9:AX9) -> 708
A10: 45512 | B10: 木曜日 | C10: 10 | D10: 10 | E10: 8 | F10: 10 | G10: 8 | H10: 10 | I10: 8 | J10: 10 | K10: 8 | L10: 8 | M10: 10 | N10: 10 | O10: 8 | P10: 10 | Q10: 12 | R10: 12 | S10: 18 | T10: 22 | U10: 24 | V10: 28 | W10: 28 | X10: 28 | Y10: 26 | Z10: 24 | AA10: 26 | AB10: 28 | AC10: 26 | AD10: 26 | AE10: 28 | AF10: 28 | AG10: 26 | AH10: 24 | AI10: 22 | AJ10: 20 | AK10: 20 | AL10: 12 | AM10: 14 | AN10: 14 | AO10: 12 | AP10: 14 | AQ10: 12 | AR10: 10 | AS10: 10 | AT10: 12 | AU10: 10 | AV10: 8 | AW10: 12 | AX10: 8 | AY10: =SUM(C10:AX10) -> 772
A11: 45513 | B11: 金曜日 | C11: 10 | D11: 10 | E11: 10 | F11: 8 | G11: 10 | H11: 8 | I11: 10 | J11: 8 | K11: 10 | L11: 10 | M11: 8 | N11: 10 | O11: 10 | P11: 10 | Q11: 12 | R11: 12 | S11: 16 | T11: 22 | U11: 24 | V11: 26 | W11: 26 | X11: 24 | Y11: 26 | Z11: 30 | AA11: 26 | AB11: 28 | AC11: 26 | AD11: 24 | AE11: 22 | AF11: 24 | AG11: 28 | AH11: 22 | AI11: 22 | AJ11: 22 | AK11: 20 | AL11: 18 | AM11: 18 | AN11: 14 | AO11: 16 | AP11: 16 | AQ11: 14 | AR11: 14 | AS11: 10 | AT11: 8 | AU11: 10 | AV11: 8 | AW11: 8 | AX11: 8 | AY11: =SUM(C11:AX11) -> 776
A12: 45514 | B12: 土曜日 | C12: 8 | D12: 8 | E12: 6 | F12: 10 | G12: 6 | H12: 8 | I12: 8 | J12: 8 | K12: 6 | L12: 8 | M12: 8 | N12: 12 | O12: 12 | P12: 12 | Q12: 12 | R12: 14 | S12: 12 | T12: 14 | U12: 12 | V12: 14 | W12: 12 | X12: 14 | Y12: 14 | Z12: 14 | AA12: 14 | AB12: 14 | AC12: 14 | AD12: 12 | AE12: 14 | AF12: 12 | AG12: 14 | AH12: 12 | AI12: 14 | AJ12: 12 | AK12: 14 | AL12: 16 | AM12: 14 | AN12: 14 | AO12: 14 | AP12: 14 | AQ12: 14 | AR12: 12 | AS12: 14 | AT12: 10 | AU12: 8 | AV12: 8 | AW12: 8 | AX12: 8 | AY12: =SUM(C12:AX12) -> 552
A13: 45515 | B13: 日曜日 | C13: 8 | D13: 6 | E13: 8 | F13: 8 | G13: 6 | H13: 8 | I13: 8 | J13: 6 | K13: 8 | L13: 8 | M13: 6 | N13: 8 | O13: 10 | P13: 12 | Q13: 12 | R13: 14 | S13: 14 | T13: 12 | U13: 14 | V13: 12 | W13: 12 | X13: 14 | Y13: 16 | Z13: 14 | AA13: 14 | AB13: 18 | AC13: 16 | AD13: 16 | AE13: 14 | AF13: 12 | AG13: 14 | AH13: 16 | AI13: 14 | AJ13: 14 | AK13: 14 | AL13: 12 | AM13: 12 | AN13: 14 | AO13: 14 | AP13: 12 | AQ13: 12 | AR13: 12 | AS13: 10 | AT13: 10 | AU13: 10 | AV13: 8 | AW13: 10 | AX13: 10 | AY13: =SUM(C13:AX13) -> 552
A14: 45516 | B14: 月曜日 | C14: 8 | D14: 10 | E14: 8 | F14: 10 | G14: 8 | H14: 10 | I14: 8 | J14: 10 | K14: 10 | L14: 8 | M14: 10 | N14: 12 | O14: 10 | P14: 14 | Q14: 14 | R14: 18 | S14: 20 | T14: 24 | U14: 24 | V14: 26 | W14: 26 | X14: 26 | Y14: 26 | Z14: 26 | AA14: 26 | AB14: 26 | AC14: 26 | AD14: 24 | AE14: 24 | AF14: 22 | AG14: 20 | AH14: 22 | AI14: 20 | AJ14: 20 | AK14: 18 | AL14: 18 | AM14: 18 | AN14: 18 | AO14: 18 | AP14: 18 | AQ14: 16 | AR14: 16 | AS14: 14 | AT14: 14 | AU14: 14 | AV14: 16 | AW14: 10 | AX14: 8 | AY14: =SUM(C14:AX14) -> 812
... A367: 45869 | B367: 木曜日 | C367: 14 | D367: 16 | E367: 14 | F367: 14 | G367: 16 | H367: 14 | I367: 16 | J367: 14 | K367: 14 | L367: 16 | M367: 14 | N367: 14 | O367: 16 | P367: 14 | Q367: 16 | R367: 18 | S367: 26 | T367: 30 | U367: 32 | V367: 32 | W367: 32 | X367: 32 | Y367: 32 | Z367: 32 | AA367: 32 | AB367: 36 | AC367: 34 | AD367: 34 | AE367: 32 | AF367: 32 | AG367: 30 | AH367: 28 | AI367: 28 | AJ367: 30 | AK367: 28 | AL367: 22 | AM367: 20 | AN367: 16 | AO367: 16 | AP367: 14 | AQ367: 14 | AR367: 14 | AS367: 12 | AT367: 12 | AU367: 12 | AV367: 12 | AW367: 10 | AX367: 12 | AY367: =SUM(C367:AX367) -> 1018
AY368: =SUM(AY3:AY367) -> 293066

Sheet 5.古平町3タス5
A1: 古平町高齢者総合支援センター（元気プラザ）
A2: 日付 | B2: 曜日 | C2: 0.020833333 | D2: 0.041666667 | E2: 0.0625 | F2: 0.083333333 | G2: 0.10416667 | H2: 0.125 | I2: 0.14583333 | J2: 0.16666667 | K2: 0.1875 | L2: 0.20833333 | M2: 0.22916667 | N2: 0.25 | O2: 0.27083333 | P2: 0.29166667 | Q2: 0.3125 | R2: 0.33333333 | S2: 0.35416667 | T2: 0.375 | U2: 0.39583333 | V2: 0.41666667 | W2: 0.4375 | X2: 0.45833333 | Y2: 0.47916667 | Z2: 0.5 | AA2: 0.52083333 | AB2: 0.54166667 | AC2: 0.5625 | AD2: 0.58333333 | AE2: 0.60416667 | AF2: 0.625 | AG2: 0.64583333 | AH2: 0.66666667 | AI2: 0.6875 | AJ2: 0.70833333 | AK2: 0.72916667 | AL2: 0.75 | AM2: 0.77083333 | AN2: 0.79166667 | AO2: 0.8125 | AP2: 0.83333333 | AQ2: 0.85416667 | AR2: 0.875 | AS2: 0.89583333 | AT2: 0.91666667 | AU2: 0.9375 | AV2: 0.95833333 | AW2: 0.97916667 | AX2: 0 | AY2: 日別合計
A3: 45505 | B3: 木曜日 | C3: ='3.古平町立診療所海のまちクリニック'!C3+'5.古平町高齢者総合支援センター'!C3 -> 18 | D3: ='3.古平町立診療所海のまちクリニック'!D3+'5.古平町高齢者総合支援センター'!D3 -> 16 | E3: ='3.古平町立診療所海のまちクリニック'!E3+'5.古平町高齢者総合支援センター'!E3 -> 16 | F3: ='3.古平町立診療所海のまちクリニック'!F3+'5.古平町高齢者総合支援センター'!F3 -> 18 | G3: ='3.古平町立診療所海のまちクリニック'!G3+'5.古平町高齢者総合支援センター'!G3 -> 16 | H3: ='3.古平町立診療所海のまちクリニック'!H3+'5.古平町高齢者総合支援センター'!H3 -> 18 | I3: ='3.古平町立診療所海のまちクリニック'!I3+'5.古平町高齢者総合支援センター'!I3 -> 18 | J3: ='3.古平町立診療所海のまちクリニック'!J3+'5.古平町高齢者総合支援センター'!J3 -> 16 | ... AY3: ='3.古平町立診療所海のまちクリニック'!AY3+'5.古平町高齢者総合支援センター'!AY3 -> 1360
A4: 45506 | B4: 金曜日 | C4: ='3.古平町立診療所海のまちクリニック'!C4+'5.古平町高齢者総合支援センター'!C4 -> 18 | D4: ='3.古平町立診療所海のまちクリニック'!D4+'5.古平町高齢者総合支援センター'!D4 -> 16 | E4: ='3.古平町立診療所海のまちクリニック'!E4+'5.古平町高齢者総合支援センター'!E4 -> 18 | F4: ='3.古平町立診療所海のまちクリニック'!F4+'5.古平町高齢者総合支援センター'!F4 -> 18 | G4: ='3.古平町立診療所海のまちクリニック'!G4+'5.古平町高齢者総合支援センター'!G4 -> 16 | H4: ='3.古平町立診療所海のまちクリニック'!H4+'5.古平町高齢者総合支援センター'!H4 -> 18 | I4: ='3.古平町立診療所海のまちクリニック'!I4+'5.古平町高齢者総合支援センター'!I4 -> 16 | J4: ='3.古平町立診療所海のまちクリニック'!J4+'5.古平町高齢者総合支援センター'!J4 -> 16 | ... AY4: ='3.古平町立診療所海のまちクリニック'!AY4+'5.古平町高齢者総合支援センター'!AY4 -> 1586
A5: 45507 | B5: 土曜日 | C5: ='3.古平町立診療所海のまちクリニック'!C5+'5.古平町高齢者総合支援センター'!C5 -> 20 | D5: ='3.古平町立診療所海のまちクリニック'!D5+'5.古平町高齢者総合支援センター'!D5 -> 18 | E5: ='3.古平町立診療所海のまちクリニック'!E5+'5.古平町高齢者総合支援センター'!E5 -> 20 | F5: ='3.古平町立診療所海のまちクリニック'!F5+'5.古平町高齢者総合支援センター'!F5 -> 16 | G5: ='3.古平町立診療所海のまちクリニック'!G5+'5.古平町高齢者総合支援センター'!G5 -> 20 | H5: ='3.古平町立診療所海のまちクリニック'!H5+'5.古平町高齢者総合支援センター'!H5 -> 18 | I5: ='3.古平町立診療所海のまちクリニック'!I5+'5.古平町高齢者総合支援センター'!I5 -> 16 | J5: ='3.古平町立診療所海のまちクリニック'!J5+'5.古平町高齢者総合支援センター'!J5 -> 20 | ... AY5: ='3.古平町立診療所海のまちクリニック'!AY5+'5.古平町高齢者総合支援センター'!AY5 -> 1438
A6: 45508 | B6: 日曜日 | C6: ='3.古平町立診療所海のまちクリニック'!C6+'5.古平町高齢者総合支援センター'!C6 -> 20 | D6: ='3.古平町立診療所海のまちクリニック'!D6+'5.古平町高齢者総合支援センター'!D6 -> 20 | E6: ='3.古平町立診療所海のまちクリニック'!E6+'5.古平町高齢者総合支援センター'!E6 -> 18 | F6: ='3.古平町立診療所海のまちクリニック'!F6+'5.古平町高齢者総合支援センター'!F6 -> 18 | G6: ='3.古平町立診療所海のまちクリニック'!G6+'5.古平町高齢者総合支援センター'!G6 -> 18 | H6: ='3.古平町立診療所海のまちクリニック'!H6+'5.古平町高齢者総合支援センター'!H6 -> 20 | I6: ='3.古平町立診療所海のまちクリニック'!I6+'5.古平町高齢者総合支援センター'!I6 -> 18 | J6: ='3.古平町立診療所海のまちクリニック'!J6+'5.古平町高齢者総合支援センター'!J6 -> 18 | ... AY6: ='3.古平町立診療所海のまちクリニック'!AY6+'5.古平町高齢者総合支援センター'!AY6 -> 942
A7: 45509 | B7: 月曜日 | C7: ='3.古平町立診療所海のまちクリニック'!C7+'5.古平町高齢者総合支援センター'!C7 -> 18 | D7: ='3.古平町立診療所海のまちクリニック'!D7+'5.古平町高齢者総合支援センター'!D7 -> 16 | E7: ='3.古平町立診療所海のまちクリニック'!E7+'5.古平町高齢者総合支援センター'!E7 -> 14 | F7: ='3.古平町立診療所海のまちクリニック'!F7+'5.古平町高齢者総合支援センター'!F7 -> 18 | G7: ='3.古平町立診療所海のまちクリニック'!G7+'5.古平町高齢者総合支援センター'!G7 -> 16 | H7: ='3.古平町立診療所海のまちクリニック'!H7+'5.古平町高齢者総合支援センター'!H7 -> 16 | I7: ='3.古平町立診療所海のまちクリニック'!I7+'5.古平町高齢者総合支援センター'!I7 -> 18 | J7: ='3.古平町立診療所海のまちクリニック'!J7+'5.古平町高齢者総合支援センター'!J7 -> 16 | ... AY7: ='3.古平町立診療所海のまちクリニック'!AY7+'5.古平町高齢者総合支援センター'!AY7 -> 1256
A8: 45510 | B8: 火曜日 | C8: ='3.古平町立診療所海のまちクリニック'!C8+'5.古平町高齢者総合支援センター'!C8 -> 16 | D8: ='3.古平町立診療所海のまちクリニック'!D8+'5.古平町高齢者総合支援センター'!D8 -> 18 | E8: ='3.古平町立診療所海のまちクリニック'!E8+'5.古平町高齢者総合支援センター'!E8 -> 16 | F8: ='3.古平町立診療所海のまちクリニック'!F8+'5.古平町高齢者総合支援センター'!F8 -> 16 | G8: ='3.古平町立診療所海のまちクリニック'!G8+'5.古平町高齢者総合支援センター'!G8 -> 18 | H8: ='3.古平町立診療所海のまちクリニック'!H8+'5.古平町高齢者総合支援センター'!H8 -> 16 | I8: ='3.古平町立診療所海のまちクリニック'!I8+'5.古平町高齢者総合支援センター'!I8 -> 16 | J8: ='3.古平町立診療所海のまちクリニック'!J8+'5.古平町高齢者総合支援センター'!J8 -> 18 | ... AY8: ='3.古平町立診療所海のまちクリニック'!AY8+'5.古平町高齢者総合支援センター'!AY8 -> 1350
A9: 45511 | B9: 水曜日 | C9: ='3.古平町立診療所海のまちクリニック'!C9+'5.古平町高齢者総合支援センター'!C9 -> 16 | D9: ='3.古平町立診療所海のまちクリニック'!D9+'5.古平町高齢者総合支援センター'!D9 -> 16 | E9: ='3.古平町立診療所海のまちクリニック'!E9+'5.古平町高齢者総合支援センター'!E9 -> 18 | F9: ='3.古平町立診療所海のまちクリニック'!F9+'5.古平町高齢者総合支援センター'!F9 -> 18 | G9: ='3.古平町立診療所海のまちクリニック'!G9+'5.古平町高齢者総合支援センター'!G9 -> 18 | H9: ='3.古平町立診療所海のまちクリニック'!H9+'5.古平町高齢者総合支援センター'!H9 -> 18 | I9: ='3.古平町立診療所海のまちクリニック'!I9+'5.古平町高齢者総合支援センター'!I9 -> 16 | J9: ='3.古平町立診療所海のまちクリニック'!J9+'5.古平町高齢者総合支援センター'!J9 -> 16 | ... AY9: ='3.古平町立診療所海のまちクリニック'!AY9+'5.古平町高齢者総合支援センター'!AY9 -> 1528
A10: 45512 | B10: 木曜日 | C10: ='3.古平町立診療所海のまちクリニック'!C10+'5.古平町高齢者総合支援センター'!C10 -> 18 | D10: ='3.古平町立診療所海のまちクリニック'!D10+'5.古平町高齢者総合支援センター'!D10 -> 18 | E10: ='3.古平町立診療所海のまちクリニック'!E10+'5.古平町高齢者総合支援センター'!E10 -> 18 | F10: ='3.古平町立診療所海のまちクリニック'!F10+'5.古平町高齢者総合支援センター'!F10 -> 18 | G10: ='3.古平町立診療所海のまちクリニック'!G10+'5.古平町高齢者総合支援センター'!G10 -> 16 | H10: ='3.古平町立診療所海のまちクリニック'!H10+'5.古平町高齢者総合支援センター'!H10 -> 18 | I10: ='3.古平町立診療所海のまちクリニック'!I10+'5.古平町高齢者総合支援センター'!I10 -> 16 | J10: ='3.古平町立診療所海のまちクリニック'!J10+'5.古平町高齢者総合支援センター'!J10 -> 18 | ... AY10: ='3.古平町立診療所海のまちクリニック'!AY10+'5.古平町高齢者総合支援センター'!AY10 -> 1652
A11: 45513 | B11: 金曜日 | C11: ='3.古平町立診療所海のまちクリニック'!C11+'5.古平町高齢者総合支援センター'!C11 -> 20 | D11: ='3.古平町立診療所海のまちクリニック'!D11+'5.古平町高齢者総合支援センター'!D11 -> 18 | E11: ='3.古平町立診療所海のまちクリニック'!E11+'5.古平町高齢者総合支援センター'!E11 -> 20 | F11: ='3.古平町立診療所海のまちクリニック'!F11+'5.古平町高齢者総合支援センター'!F11 -> 18 | G11: ='3.古平町立診療所海のまちクリニック'!G11+'5.古平町高齢者総合支援センター'!G11 -> 18 | H11: ='3.古平町立診療所海のまちクリニック'!H11+'5.古平町高齢者総合支援センター'!H11 -> 16 | I11: ='3.古平町立診療所海のまちクリニック'!I11+'5.古平町高齢者総合支援センター'!I11 -> 20 | J11: ='3.古平町立診療所海のまちクリニック'!J11+'5.古平町高齢者総合支援センター'!J11 -> 16 | ... AY11: ='3.古平町立診療所海のまちクリニック'!AY11+'5.古平町高齢者総合支援センター'!AY11 -> 1706
A12: 45514 | B12: 土曜日 | C12: ='3.古平町立診療所海のまちクリニック'!C12+'5.古平町高齢者総合支援センター'!C12 -> 20 | D12: ='3.古平町立診療所海のまちクリニック'!D12+'5.古平町高齢者総合支援センター'!D12 -> 20 | E12: ='3.古平町立診療所海のまちクリニック'!E12+'5.古平町高齢者総合支援センター'!E12 -> 18 | F12: ='3.古平町立診療所海のまちクリニック'!F12+'5.古平町高齢者総合支援センター'!F12 -> 22 | G12: ='3.古平町立診療所海のまちクリニック'!G12+'5.古平町高齢者総合支援センター'!G12 -> 18 | H12: ='3.古平町立診療所海のまちクリニック'!H12+'5.古平町高齢者総合支援センター'!H12 -> 20 | I12: ='3.古平町立診療所海のまちクリニック'!I12+'5.古平町高齢者総合支援センター'!I12 -> 20 | J12: ='3.古平町立診療所海のまちクリニック'!J12+'5.古平町高齢者総合支援センター'!J12 -> 20 | ... AY12: ='3.古平町立診療所海のまちクリニック'!AY12+'5.古平町高齢者総合支援センター'!AY12 -> 1216
A13: 45515 | B13: 日曜日 | C13: ='3.古平町立診療所海のまちクリニック'!C13+'5.古平町高齢者総合支援センター'!C13 -> 14 | D13: ='3.古平町立診療所海のまちクリニック'!D13+'5.古平町高齢者総合支援センター'!D13 -> 14 | E13: ='3.古平町立診療所海のまちクリニック'!E13+'5.古平町高齢者総合支援センター'!E13 -> 14 | F13: ='3.古平町立診療所海のまちクリニック'!F13+'5.古平町高齢者総合支援センター'!F13 -> 16 | G13: ='3.古平町立診療所海のまちクリニック'!G13+'5.古平町高齢者総合支援センター'!G13 -> 14 | H13: ='3.古平町立診療所海のまちクリニック'!H13+'5.古平町高齢者総合支援センター'!H13 -> 16 | I13: ='3.古平町立診療所海のまちクリニック'!I13+'5.古平町高齢者総合支援センター'!I13 -> 14 | J13: ='3.古平町立診療所海のまちクリニック'!J13+'5.古平町高齢者総合支援センター'!J13 -> 14 | ... AY13: ='3.古平町立診療所海のまちクリニック'!AY13+'5.古平町高齢者総合支援センター'!AY13 -> 1212
A14: 45516 | B14: 月曜日 | C14: ='3.古平町立診療所海のまちクリニック'!C14+'5.古平町高齢者総合支援センター'!C14 -> 16 | D14: ='3.古平町立診療所海のまちクリニック'!D14+'5.古平町高齢者総合支援センター'!D14 -> 20 | E14: ='3.古平町立診療所海のまちクリニック'!E14+'5.古平町高齢者総合支援センター'!E14 -> 18 | F14: ='3.古平町立診療所海のまちクリニック'!F14+'5.古平町高齢者総合支援センター'!F14 -> 18 | G14: ='3.古平町立診療所海のまちクリニック'!G14+'5.古平町高齢者総合支援センター'!G14 -> 16 | H14: ='3.古平町立診療所海のまちクリニック'!H14+'5.古平町高齢者総合支援センター'!H14 -> 16 | I14: ='3.古平町立診療所海のまちクリニック'!I14+'5.古平町高齢者総合支援センター'!I14 -> 18 | J14: ='3.古平町立診療所海のまちクリニック'!J14+'5.古平町高齢者総合支援センター'!J14 -> 16 | ... AY14: ='3.古平町立診療所海のまちクリニック'!AY14+'5.古平町高齢者総合支援センター'!AY14 -> 1606
... A367: 45869 | B367: 木曜日 | C367: ='3.古平町立診療所海のまちクリニック'!C367+'5.古平町高齢者総合支援センター'!C367 -> 26 | D367: ='3.古平町立診療所海のまちクリニック'!D367+'5.古平町高齢者総合支援センター'!D367 -> 28 | E367: ='3.古平町立診療所海のまちクリニック'!E367+'5.古平町高齢者総合支援センター'!E367 -> 26 | F367: ='3.古平町立診療所海のまちクリニック'!F367+'5.古平町高齢者総合支援センター'!F367 -> 26 | G367: ='3.古平町立診療所海のまちクリニック'!G367+'5.古平町高齢者総合支援センター'!G367 -> 24 | H367: ='3.古平町立診療所海のまちクリニック'!H367+'5.古平町高齢者総合支援センター'!H367 -> 24 | I367: ='3.古平町立診療所海のまちクリニック'!I367+'5.古平町高齢者総合支援センター'!I367 -> 26 | J367: ='3.古平町立診療所海のまちクリニック'!J367+'5.古平町高齢者総合支援センター'!J367 -> 24 | ... AY367: ='3.古平町立診療所海のまちクリニック'!AY367+'5.古平町高齢者総合支援センター'!AY367 -> 2086
AY368: =SUM(AY3:AY367) -> 578312

Sheet 4.古平町温泉保養センター
A1: 古平町温泉保養センター（日本海ふるびら温泉しおかぜ）
A2: 日付 | B2: 曜日 | C2: 0.020833333 | D2: 0.041666667 | E2: 0.0625 | F2: 0.083333333 | G2: 0.10416667 | H2: 0.125 | I2: 0.14583333 | J2: 0.16666667 | K2: 0.1875 | L2: 0.20833333 | M2: 0.22916667 | N2: 0.25 | O2: 0.27083333 | P2: 0.29166667 | Q2: 0.3125 | R2: 0.33333333 | S2: 0.35416667 | T2: 0.375 | U2: 0.39583333 | V2: 0.41666667 | W2: 0.4375 | X2: 0.45833333 | Y2: 0.47916667 | Z2: 0.5 | AA2: 0.52083333 | AB2: 0.54166667 | AC2: 0.5625 | AD2: 0.58333333 | AE2: 0.60416667 | AF2: 0.625 | AG2: 0.64583333 | AH2: 0.66666667 | AI2: 0.6875 | AJ2: 0.70833333 | AK2: 0.72916667 | AL2: 0.75 | AM2: 0.77083333 | AN2: 0.79166667 | AO2: 0.8125 | AP2: 0.83333333 | AQ2: 0.85416667 | AR2: 0.875 | AS2: 0.89583333 | AT2: 0.91666667 | AU2: 0.9375 | AV2: 0.95833333 | AW2: 0.97916667 | AX2: 0 | AY2: 日別合計
A3: 45505 | B3: 木曜日 | C3: 14 | D3: 14 | E3: 16 | F3: 14 | G3: 14 | H3: 16 | I3: 14 | J3: 14 | K3: 14 | L3: 14 | M3: 14 | N3: 16 | O3: 18 | P3: 16 | Q3: 16 | R3: 26 | S3: 28 | T3: 22 | U3: 22 | V3: 20 | W3: 24 | X3: 22 | Y3: 24 | Z3: 20 | AA3: 24 | AB3: 20 | AC3: 22 | AD3: 22 | AE3: 24 | AF3: 22 | AG3: 22 | AH3: 24 | AI3: 26 | AJ3: 24 | AK3: 22 | AL3: 20 | AM3: 26 | AN3: 22 | AO3: 26 | AP3: 24 | AQ3: 22 | AR3: 18 | AS3: 18 | AT3: 14 | AU3: 14 | AV3: 14 | AW3: 12 | AX3: 14 | AY3: =SUM(C3:AX3) -> 928
A4: 45506 | B4: 金曜日 | C4: 14 | D4: 14 | E4: 12 | F4: 14 | G4: 14 | H4: 12 | I4: 14 | J4: 14 | K4: 12 | L4: 14 | M4: 14 | N4: 14 | O4: 14 | P4: 22 | Q4: 28 | R4: 22 | S4: 24 | T4: 24 | U4: 22 | V4: 22 | W4: 20 | X4: 22 | Y4: 24 | Z4: 22 | AA4: 24 | AB4: 22 | AC4: 24 | AD4: 22 | AE4: 24 | AF4: 22 | AG4: 26 | AH4: 24 | AI4: 24 | AJ4: 26 | AK4: 22 | AL4: 24 | AM4: 26 | AN4: 26 | AO4: 26 | AP4: 26 | AQ4: 26 | AR4: 24 | AS4: 18 | AT4: 16 | AU4: 16 | AV4: 16 | AW4: 16 | AX4: 16 | AY4: =SUM(C4:AX4) -> 964
A5: 45507 | B5: 土曜日 | C5: 16 | D5: 16 | E5: 14 | F5: 16 | G5: 14 | H5: 14 | I5: 16 | J5: 14 | K5: 14 | L5: 14 | M5: 14 | N5: 18 | O5: 16 | P5: 18 | Q5: 16 | R5: 18 | S5: 28 | T5: 28 | U5: 24 | V5: 22 | W5: 22 | X5: 22 | Y5: 24 | Z5: 24 | AA5: 26 | AB5: 22 | AC5: 24 | AD5: 22 | AE5: 26 | AF5: 22 | AG5: 24 | AH5: 28 | AI5: 24 | AJ5: 24 | AK5: 26 | AL5: 24 | AM5: 26 | AN5: 26 | AO5: 28 | AP5: 26 | AQ5: 26 | AR5: 24 | AS5: 16 | AT5: 16 | AU5: 16 | AV5: 14 | AW5: 16 | AX5: 16 | AY5: =SUM(C5:AX5) -> 984
A6: 45508 | B6: 日曜日 | C6: 14 | D6: 16 | E6: 16 | F6: 14 | G6: 16 | H6: 14 | I6: 14 | J6: 14 | K6: 16 | L6: 14 | M6: 14 | N6: 18 | O6: 16 | P6: 18 | Q6: 18 | R6: 16 | S6: 30 | T6: 28 | U6: 22 | V6: 24 | W6: 22 | X6: 22 | Y6: 22 | Z6: 26 | AA6: 24 | AB6: 24 | AC6: 22 | AD6: 22 | AE6: 22 | AF6: 24 | AG6: 30 | AH6: 26 | AI6: 26 | AJ6: 26 | AK6: 24 | AL6: 22 | AM6: 28 | AN6: 28 | AO6: 26 | AP6: 26 | AQ6: 24 | AR6: 24 | AS6: 16 | AT6: 18 | AU6: 14 | AV6: 14 | AW6: 14 | AX6: 16 | AY6: =SUM(C6:AX6) -> 984
A7: 45509 | B7: 月曜日 | C7: 14 | D7: 14 | E7: 14 | F7: 16 | G7: 14 | H7: 14 | I7: 14 | J7: 16 | K7: 14 | L7: 14 | M7: 14 | N7: 14 | O7: 14 | P7: 16 | Q7: 18 | R7: 16 | S7: 18 | T7: 28 | U7: 30 | V7: 22 | W7: 22 | X7: 26 | Y7: 24 | Z7: 22 | AA7: 26 | AB7: 22 | AC7: 22 | AD7: 22 | AE7: 22 | AF7: 26 | AG7: 22 | AH7: 24 | AI7: 24 | AJ7: 24 | AK7: 26 | AL7: 26 | AM7: 24 | AN7: 22 | AO7: 26 | AP7: 26 | AQ7: 28 | AR7: 20 | AS7: 16 | AT7: 16 | AU7: 14 | AV7: 14 | AW7: 14 | AX7: 14 | AY7: =SUM(C7:AX7) -> 948
A8: 45510 | B8: 火曜日 | C8: 14 | D8: 14 | E8: 16 | F8: 14 | G8: 14 | H8: 14 | I8: 14 | J8: 14 | K8: 14 | L8: 14 | M8: 16 | N8: 14 | O8: 16 | P8: 16 | Q8: 16 | R8: 20 | S8: 28 | T8: 24 | U8: 24 | V8: 22 | W8: 22 | X8: 22 | Y8: 24 | Z8: 20 | AA8: 24 | AB8: 24 | AC8: 24 | AD8: 22 | AE8: 22 | AF8: 24 | AG8: 22 | AH8: 22 | AI8: 22 | AJ8: 22 | AK8: 24 | AL8: 22 | AM8: 24 | AN8: 26 | AO8: 26 | AP8: 24 | AQ8: 26 | AR8: 22 | AS8: 20 | AT8: 18 | AU8: 16 | AV8: 16 | AW8: 14 | AX8: 14 | AY8: =SUM(C8:AX8) -> 946
A9: 45511 | B9: 水曜日 | C9: 16 | D9: 14 | E9: 14 | F9: 14 | G9: 16 | H9: 14 | I9: 14 | J9: 14 | K9: 14 | L9: 14 | M9: 14 | N9: 14 | O9: 14 | P9: 16 | Q9: 18 | R9: 16 | S9: 22 | T9: 30 | U9: 24 | V9: 22 | W9: 24 | X9: 22 | Y9: 24 | Z9: 22 | AA9: 22 | AB9: 24 | AC9: 20 | AD9: 20 | AE9: 22 | AF9: 24 | AG9: 24 | AH9: 24 | AI9: 26 | AJ9: 24 | AK9: 22 | AL9: 26 | AM9: 26 | AN9: 24 | AO9: 26 | AP9: 26 | AQ9: 24 | AR9: 26 | AS9: 16 | AT9: 16 | AU9: 14 | AV9: 14 | AW9: 14 | AX9: 12 | AY9: =SUM(C9:AX9) -> 942
A10: 45512 | B10: 木曜日 | C10: 14 | D10: 14 | E10: 12 | F10: 14 | G10: 14 | H10: 14 | I10: 12 | J10: 14 | K10: 12 | L10: 14 | M10: 16 | N10: 16 | O10: 16 | P10: 18 | Q10: 16 | R10: 24 | S10: 28 | T10: 22 | U10: 22 | V10: 22 | W10: 24 | X10: 24 | Y10: 22 | Z10: 20 | AA10: 24 | AB10: 22 | AC10: 24 | AD10: 20 | AE10: 22 | AF10: 22 | AG10: 24 | AH10: 22 | AI10: 24 | AJ10: 22 | AK10: 26 | AL10: 22 | AM10: 22 | AN10: 24 | AO10: 26 | AP10: 26 | AQ10: 22 | AR10: 18 | AS10: 16 | AT10: 16 | AU10: 14 | AV10: 14 | AW10: 12 | AX10: 14 | AY10: =SUM(C10:AX10) -> 922
A11: 45513 | B11: 金曜日 | C11: 14 | D11: 12 | E11: 14 | F11: 14 | G11: 12 | H11: 14 | I11: 16 | J11: 14 | K11: 14 | L11: 14 | M11: 14 | N11: 16 | O11: 14 | P11: 20 | Q11: 28 | R11: 22 | S11: 24 | T11: 24 | U11: 22 | V11: 20 | W11: 22 | X11: 22 | Y11: 24 | Z11: 24 | AA11: 24 | AB11: 22 | AC11: 22 | AD11: 24 | AE11: 24 | AF11: 22 | AG11: 24 | AH11: 24 | AI11: 24 | AJ11: 24 | AK11: 22 | AL11: 24 | AM11: 30 | AN11: 26 | AO11: 24 | AP11: 28 | AQ11: 28 | AR11: 20 | AS11: 20 | AT11: 16 | AU11: 16 | AV11: 16 | AW11: 14 | AX11: 16 | AY11: =SUM(C11:AX11) -> 968
A12: 45514 | B12: 土曜日 | C12: 14 | D12: 14 | E12: 14 | F12: 14 | G12: 14 | H12: 16 | I12: 14 | J12: 14 | K12: 14 | L12: 14 | M12: 16 | N12: 14 | O12: 14 | P12: 14 | Q12: 18 | R12: 16 | S12: 18 | T12: 30 | U12: 28 | V12: 22 | W12: 24 | X12: 24 | Y12: 22 | Z12: 24 | AA12: 24 | AB12: 22 | AC12: 24 | AD12: 24 | AE12: 22 | AF12: 22 | AG12: 24 | AH12: 28 | AI12: 28 | AJ12: 28 | AK12: 28 | AL12: 26 | AM12: 30 | AN12: 28 | AO12: 28 | AP12: 28 | AQ12: 30 | AR12: 28 | AS12: 18 | AT12: 18 | AU12: 16 | AV12: 14 | AW12: 14 | AX12: 16 | AY12: =SUM(C12:AX12) -> 994
A13: 45515 | B13: 日曜日 | C13: 14 | D13: 14 | E13: 16 | F13: 14 | G13: 14 | H13: 16 | I13: 14 | J13: 14 | K13: 14 | L13: 16 | M13: 14 | N13: 16 | O13: 18 | P13: 18 | Q13: 18 | R13: 20 | S13: 28 | T13: 26 | U13: 24 | V13: 22 | W13: 24 | X13: 24 | Y13: 22 | Z13: 22 | AA13: 24 | AB13: 26 | AC13: 22 | AD13: 22 | AE13: 24 | AF13: 24 | AG13: 24 | AH13: 24 | AI13: 26 | AJ13: 28 | AK13: 28 | AL13: 28 | AM13: 28 | AN13: 30 | AO13: 34 | AP13: 34 | AQ13: 32 | AR13: 26 | AS13: 20 | AT13: 18 | AU13: 14 | AV13: 16 | AW13: 16 | AX13: 16 | AY13: =SUM(C13:AX13) -> 1026
A14: 45516 | B14: 月曜日 | C14: 14 | D14: 14 | E14: 16 | F14: 14 | G14: 14 | H14: 14 | I14: 16 | J14: 14 | K14: 14 | L14: 16 | M14: 14 | N14: 14 | O14: 14 | P14: 18 | Q14: 16 | R14: 18 | S14: 20 | T14: 30 | U14: 30 | V14: 24 | W14: 24 | X14: 22 | Y14: 26 | Z14: 22 | AA14: 24 | AB14: 24 | AC14: 24 | AD14: 24 | AE14: 24 | AF14: 26 | AG14: 26 | AH14: 26 | AI14: 26 | AJ14: 26 | AK14: 28 | AL14: 30 | AM14: 28 | AN14: 28 | AO14: 30 | AP14: 34 | AQ14: 30 | AR14: 24 | AS14: 18 | AT14: 16 | AU14: 14 | AV14: 14 | AW14: 16 | AX14: 14 | AY14: =SUM(C14:AX14) -> 1012
... A367: 45869 | B367: 木曜日 | C367: 14 | D367: 14 | E367: 14 | F367: 14 | G367: 14 | H367: 14 | I367: 14 | J367: 14 | K367: 14 | L367: 16 | M367: 14 | N367: 18 | O367: 16 | P367: 16 | Q367: 16 | R367: 18 | S367: 18 | T367: 30 | U367: 26 | V367: 22 | W367: 22 | X367: 22 | Y367: 20 | Z367: 22 | AA367: 24 | AB367: 24 | AC367: 22 | AD367: 20 | AE367: 22 | AF367: 22 | AG367: 22 | AH367: 24 | AI367: 20 | AJ367: 20 | AK367: 22 | AL367: 22 | AM367: 24 | AN367: 24 | AO367: 26 | AP367: 24 | AQ367: 26 | AR367: 18 | AS367: 16 | AT367: 16 | AU367: 14 | AV367: 14 | AW367: 12 | AX367: 14 | AY367: =SUM(C367:AX367) -> 914
AY368: =SUM(AY3:AY367) -> 345998

Sheet 6.古平町下水道管理センター水処理棟
A1: 古平町下水道管理センター 水処理棟
A2: 日付 | B2: 曜日 | C2: 0.020833333 | D2: 0.041666667 | E2: 0.0625 | F2: 0.083333333 | G2: 0.10416667 | H2: 0.125 | I2: 0.14583333 | J2: 0.16666667 | K2: 0.1875 | L2: 0.20833333 | M2: 0.22916667 | N2: 0.25 | O2: 0.27083333 | P2: 0.29166667 | Q2: 0.3125 | R2: 0.33333333 | S2: 0.35416667 | T2: 0.375 | U2: 0.39583333 | V2: 0.41666667 | W2: 0.4375 | X2: 0.45833333 | Y2: 0.47916667 | Z2: 0.5 | AA2: 0.52083333 | AB2: 0.54166667 | AC2: 0.5625 | AD2: 0.58333333 | AE2: 0.60416667 | AF2: 0.625 | AG2: 0.64583333 | AH2: 0.66666667 | AI2: 0.6875 | AJ2: 0.70833333 | AK2: 0.72916667 | AL2: 0.75 | AM2: 0.77083333 | AN2: 0.79166667 | AO2: 0.8125 | AP2: 0.83333333 | AQ2: 0.85416667 | AR2: 0.875 | AS2: 0.89583333 | AT2: 0.91666667 | AU2: 0.9375 | AV2: 0.95833333 | AW2: 0.97916667 | AX2: 0 | AY2: 日別合計
A3: 45505 | B3: 木曜日 | C3: 28 | D3: 28 | E3: 12 | F3: 10 | G3: 8 | H3: 10 | I3: 26 | J3: 26 | K3: 30 | L3: 12 | M3: 8 | N3: 10 | O3: 10 | P3: 12 | Q3: 26 | R3: 22 | S3: 20 | T3: 18 | U3: 32 | V3: 34 | W3: 40 | X3: 14 | Y3: 24 | Z3: 28 | AA3: 22 | AB3: 14 | AC3: 38 | AD3: 34 | AE3: 32 | AF3: 16 | AG3: 30 | AH3: 20 | AI3: 24 | AJ3: 18 | AK3: 10 | AL3: 14 | AM3: 34 | AN3: 36 | AO3: 30 | AP3: 26 | AQ3: 24 | AR3: 22 | AS3: 16 | AT3: 28 | AU3: 34 | AV3: 32 | AW3: 10 | AX3: 26 | AY3: =SUM(C3:AX3) -> 1078
A4: 45506 | B4: 金曜日 | C4: 34 | D4: 26 | E4: 12 | F4: 8 | G4: 12 | H4: 10 | I4: 24 | J4: 28 | K4: 32 | L4: 18 | M4: 6 | N4: 16 | O4: 8 | P4: 16 | Q4: 24 | R4: 26 | S4: 22 | T4: 12 | U4: 42 | V4: 36 | W4: 40 | X4: 20 | Y4: 24 | Z4: 28 | AA4: 24 | AB4: 14 | AC4: 36 | AD4: 38 | AE4: 36 | AF4: 16 | AG4: 28 | AH4: 28 | AI4: 24 | AJ4: 16 | AK4: 14 | AL4: 16 | AM4: 32 | AN4: 36 | AO4: 32 | AP4: 24 | AQ4: 26 | AR4: 24 | AS4: 14 | AT4: 34 | AU4: 32 | AV4: 32 | AW4: 14 | AX4: 26 | AY4: =SUM(C4:AX4) -> 1140
A5: 45507 | B5: 土曜日 | C5: 32 | D5: 34 | E5: 12 | F5: 8 | G5: 8 | H5: 8 | I5: 30 | J5: 34 | K5: 32 | L5: 18 | M5: 12 | N5: 10 | O5: 12 | P5: 18 | Q5: 22 | R5: 22 | S5: 20 | T5: 14 | U5: 32 | V5: 36 | W5: 32 | X5: 14 | Y5: 24 | Z5: 24 | AA5: 20 | AB5: 16 | AC5: 32 | AD5: 32 | AE5: 36 | AF5: 12 | AG5: 20 | AH5: 24 | AI5: 28 | AJ5: 14 | AK5: 8 | AL5: 18 | AM5: 36 | AN5: 30 | AO5: 38 | AP5: 22 | AQ5: 24 | AR5: 26 | AS5: 14 | AT5: 30 | AU5: 38 | AV5: 30 | AW5: 12 | AX5: 28 | AY5: =SUM(C5:AX5) -> 1096
A6: 45508 | B6: 日曜日 | C6: 32 | D6: 30 | E6: 12 | F6: 8 | G6: 6 | H6: 12 | I6: 28 | J6: 26 | K6: 30 | L6: 8 | M6: 8 | N6: 12 | O6: 12 | P6: 12 | Q6: 22 | R6: 20 | S6: 20 | T6: 12 | U6: 32 | V6: 36 | W6: 30 | X6: 18 | Y6: 24 | Z6: 20 | AA6: 18 | AB6: 18 | AC6: 30 | AD6: 30 | AE6: 32 | AF6: 14 | AG6: 18 | AH6: 24 | AI6: 20 | AJ6: 16 | AK6: 8 | AL6: 12 | AM6: 32 | AN6: 32 | AO6: 30 | AP6: 28 | AQ6: 22 | AR6: 22 | AS6: 14 | AT6: 28 | AU6: 32 | AV6: 34 | AW6: 8 | AX6: 26 | AY6: =SUM(C6:AX6) -> 1018
A7: 45509 | B7: 月曜日 | C7: 30 | D7: 32 | E7: 10 | F7: 6 | G7: 4 | H7: 10 | I7: 24 | J7: 32 | K7: 30 | L7: 10 | M7: 6 | N7: 8 | O7: 10 | P7: 12 | Q7: 24 | R7: 20 | S7: 18 | T7: 16 | U7: 30 | V7: 34 | W7: 40 | X7: 34 | Y7: 32 | Z7: 36 | AA7: 38 | AB7: 22 | AC7: 32 | AD7: 38 | AE7: 42 | AF7: 24 | AG7: 32 | AH7: 36 | AI7: 34 | AJ7: 18 | AK7: 10 | AL7: 14 | AM7: 28 | AN7: 32 | AO7: 36 | AP7: 20 | AQ7: 24 | AR7: 24 | AS7: 10 | AT7: 32 | AU7: 40 | AV7: 36 | AW7: 16 | AX7: 26 | AY7: =SUM(C7:AX7) -> 1172
A8: 45510 | B8: 火曜日 | C8: 26 | D8: 28 | E8: 12 | F8: 10 | G8: 8 | H8: 6 | I8: 26 | J8: 26 | K8: 30 | L8: 8 | M8: 8 | N8: 10 | O8: 12 | P8: 14 | Q8: 20 | R8: 22 | S8: 22 | T8: 12 | U8: 32 | V8: 36 | W8: 36 | X8: 18 | Y8: 26 | Z8: 26 | AA8: 22 | AB8: 18 | AC8: 34 | AD8: 34 | AE8: 36 | AF8: 18 | AG8: 26 | AH8: 28 | AI8: 26 | AJ8: 18 | AK8: 12 | AL8: 14 | AM8: 34 | AN8: 36 | AO8: 30 | AP8: 24 | AQ8: 24 | AR8: 22 | AS8: 14 | AT8: 28 | AU8: 32 | AV8: 34 | AW8: 8 | AX8: 28 | AY8: =SUM(C8:AX8) -> 1074
A9: 45511 | B9: 水曜日 | C9: 30 | D9: 30 | E9: 10 | F9: 6 | G9: 8 | H9: 6 | I9: 26 | J9: 32 | K9: 28 | L9: 10 | M9: 8 | N9: 8 | O9: 8 | P9: 18 | Q9: 28 | R9: 22 | S9: 22 | T9: 16 | U9: 36 | V9: 40 | W9: 40 | X9: 24 | Y9: 32 | Z9: 28 | AA9: 24 | AB9: 12 | AC9: 38 | AD9: 34 | AE9: 36 | AF9: 16 | AG9: 30 | AH9: 26 | AI9: 24 | AJ9: 18 | AK9: 12 | AL9: 14 | AM9: 34 | AN9: 34 | AO9: 34 | AP9: 24 | AQ9: 26 | AR9: 22 | AS9: 18 | AT9: 30 | AU9: 34 | AV9: 36 | AW9: 12 | AX9: 26 | AY9: =SUM(C9:AX9) -> 1130
A10: 45512 | B10: 木曜日 | C10: 28 | D10: 36 | E10: 8 | F10: 6 | G10: 8 | H10: 8 | I10: 26 | J10: 28 | K10: 30 | L10: 16 | M10: 10 | N10: 8 | O10: 10 | P10: 16 | Q10: 26 | R10: 28 | S10: 20 | T10: 18 | U10: 40 | V10: 36 | W10: 40 | X10: 24 | Y10: 26 | Z10: 28 | AA10: 28 | AB10: 16 | AC10: 34 | AD10: 38 | AE10: 44 | AF10: 18 | AG10: 28 | AH10: 30 | AI10: 30 | AJ10: 20 | AK10: 20 | AL10: 16 | AM10: 36 | AN10: 38 | AO10: 38 | AP10: 26 | AQ10: 30 | AR10: 24 | AS10: 16 | AT10: 34 | AU10: 32 | AV10: 32 | AW10: 16 | AX10: 26 | AY10: =SUM(C10:AX10) -> 1194
A11: 45513 | B11: 金曜日 | C11: 30 | D11: 32 | E11: 16 | F11: 10 | G11: 8 | H11: 10 | I11: 26 | J11: 30 | K11: 32 | L11: 10 | M11: 14 | N11: 14 | O11: 14 | P11: 16 | Q11: 26 | R11: 28 | S11: 18 | T11: 18 | U11: 30 | V11: 38 | W11: 42 | X11: 30 | Y11: 44 | Z11: 42 | AA11: 36 | AB11: 30 | AC11: 38 | AD11: 36 | AE11: 40 | AF11: 32 | AG11: 36 | AH11: 34 | AI11: 28 | AJ11: 30 | AK11: 28 | AL11: 20 | AM11: 40 | AN11: 38 | AO11: 36 | AP11: 28 | AQ11: 28 | AR11: 24 | AS11: 16 | AT11: 34 | AU11: 32 | AV11: 36 | AW11: 18 | AX11: 28 | AY11: =SUM(C11:AX11) -> 1324
A12: 45514 | B12: 土曜日 | C12: 30 | D12: 34 | E12: 14 | F12: 10 | G12: 10 | H12: 10 | I12: 28 | J12: 30 | K12: 38 | L12: 10 | M12: 10 | N12: 12 | O12: 12 | P12: 16 | Q12: 26 | R12: 24 | S12: 18 | T12: 16 | U12: 38 | V12: 32 | W12: 38 | X12: 20 | Y12: 22 | Z12: 24 | AA12: 20 | AB12: 12 | AC12: 34 | AD12: 34 | AE12: 36 | AF12: 12 | AG12: 22 | AH12: 30 | AI12: 22 | AJ12: 14 | AK12: 10 | AL12: 20 | AM12: 36 | AN12: 32 | AO12: 34 | AP12: 28 | AQ12: 24 | AR12: 28 | AS12: 14 | AT12: 30 | AU12: 38 | AV12: 34 | AW12: 10 | AX12: 26 | AY12: =SUM(C12:AX12) -> 1122
A13: 45515 | B13: 日曜日 | C13: 34 | D13: 32 | E13: 10 | F13: 6 | G13: 8 | H13: 8 | I13: 28 | J13: 34 | K13: 30 | L13: 18 | M13: 10 | N13: 10 | O13: 8 | P13: 18 | Q13: 26 | R13: 22 | S13: 18 | T13: 16 | U13: 32 | V13: 34 | W13: 38 | X13: 18 | Y13: 22 | Z13: 30 | AA13: 20 | AB13: 12 | AC13: 36 | AD13: 34 | AE13: 32 | AF13: 12 | AG13: 24 | AH13: 26 | AI13: 24 | AJ13: 16 | AK13: 14 | AL13: 14 | AM13: 30 | AN13: 38 | AO13: 34 | AP13: 22 | AQ13: 30 | AR13: 22 | AS13: 12 | AT13: 34 | AU13: 32 | AV13: 32 | AW13: 14 | AX13: 30 | AY13: =SUM(C13:AX13) -> 1104
A14: 45516 | B14: 月曜日 | C14: 28 | D14: 32 | E14: 14 | F14: 8 | G14: 12 | H14: 10 | I14: 24 | J14: 30 | K14: 30 | L14: 10 | M14: 8 | N14: 18 | O14: 8 | P14: 14 | Q14: 24 | R14: 24 | S14: 20 | T14: 14 | U14: 38 | V14: 32 | W14: 34 | X14: 26 | Y14: 24 | Z14: 24 | AA14: 22 | AB14: 12 | AC14: 34 | AD14: 38 | AE14: 34 | AF14: 10 | AG14: 28 | AH14: 26 | AI14: 24 | AJ14: 12 | AK14: 18 | AL14: 14 | AM14: 32 | AN14: 38 | AO14: 34 | AP14: 24 | AQ14: 30 | AR14: 24 | AS14: 12 | AT14: 36 | AU14: 32 | AV14: 36 | AW14: 14 | AX14: 28 | AY14: =SUM(C14:AX14) -> 1118
... A367: 45869 | B367: 木曜日 | C367: 30 | D367: 18 | E367: 12 | F367: 8 | G367: 12 | H367: 12 | I367: 26 | J367: 28 | K367: 16 | L367: 8 | M367: 12 | N367: 10 | O367: 10 | P367: 20 | Q367: 20 | R367: 22 | S367: 18 | T367: 12 | U367: 36 | V367: 42 | W367: 28 | X367: 20 | Y367: 26 | Z367: 28 | AA367: 16 | AB367: 16 | AC367: 36 | AD367: 34 | AE367: 20 | AF367: 12 | AG367: 26 | AH367: 22 | AI367: 16 | AJ367: 14 | AK367: 18 | AL367: 12 | AM367: 34 | AN367: 32 | AO367: 20 | AP367: 22 | AQ367: 28 | AR367: 14 | AS367: 16 | AT367: 32 | AU367: 30 | AV367: 18 | AW367: 14 | AX367: 26 | AY367: =SUM(C367:AX367) -> 1002
Q368: =MIN(Q3:Q367) -> 16 | R368: =MIN(R3:R367) -> 10 | S368: =MIN(S3:S367) -> 6 | T368: =MIN(T3:T367) -> 6 | U368: =MIN(U3:U367) -> 26 | V368: =MIN(V3:V367) -> 22 | W368: =MIN(W3:W367) -> 8 | X368: =MIN(X3:X367) -> 6 | ... AQ368: =MIN(AQ3:AQ367) -> 16 | AY368: =SUM(AY3:AY367) -> 349076

Sheet 7.古平町B&G海洋センター
A1: 古平町B&G海洋センター
A2: 日付 | B2: 曜日 | C2: 0.020833333 | D2: 0.041666667 | E2: 0.0625 | F2: 0.083333333 | G2: 0.10416667 | H2: 0.125 | I2: 0.14583333 | J2: 0.16666667 | K2: 0.1875 | L2: 0.20833333 | M2: 0.22916667 | N2: 0.25 | O2: 0.27083333 | P2: 0.29166667 | Q2: 0.3125 | R2: 0.33333333 | S2: 0.35416667 | T2: 0.375 | U2: 0.39583333 | V2: 0.41666667 | W2: 0.4375 | X2: 0.45833333 | Y2: 0.47916667 | Z2: 0.5 | AA2: 0.52083333 | AB2: 0.54166667 | AC2: 0.5625 | AD2: 0.58333333 | AE2: 0.60416667 | AF2: 0.625 | AG2: 0.64583333 | AH2: 0.66666667 | AI2: 0.6875 | AJ2: 0.70833333 | AK2: 0.72916667 | AL2: 0.75 | AM2: 0.77083333 | AN2: 0.79166667 | AO2: 0.8125 | AP2: 0.83333333 | AQ2: 0.85416667 | AR2: 0.875 | AS2: 0.89583333 | AT2: 0.91666667 | AU2: 0.9375 | AV2: 0.95833333 | AW2: 0.97916667 | AX2: 0 | AY2: 日別合計
A3: 45505 | B3: 木曜日 | C3: 12 | D3: 12 | E3: 12 | F3: 12 | G3: 12 | H3: 12 | I3: 12 | J3: 12 | K3: 12 | L3: 12 | M3: 12 | N3: 12 | O3: 12 | P3: 12 | Q3: 12 | R3: 12 | S3: 12 | T3: 12 | U3: 16 | V3: 14 | W3: 16 | X3: 14 | Y3: 16 | Z3: 14 | AA3: 16 | AB3: 14 | AC3: 18 | AD3: 16 | AE3: 18 | AF3: 16 | AG3: 14 | AH3: 14 | AI3: 14 | AJ3: 14 | AK3: 14 | AL3: 14 | AM3: 18 | AN3: 22 | AO3: 20 | AP3: 20 | AQ3: 20 | AR3: 20 | AS3: 14 | AT3: 12 | AU3: 12 | AV3: 12 | AW3: 12 | AX3: 12 | AY3: =SUM(C3:AX3) -> 682
A4: 45506 | B4: 金曜日 | C4: 12 | D4: 12 | E4: 12 | F4: 14 | G4: 12 | H4: 12 | I4: 12 | J4: 12 | K4: 12 | L4: 12 | M4: 12 | N4: 12 | O4: 12 | P4: 12 | Q4: 12 | R4: 12 | S4: 12 | T4: 12 | U4: 14 | V4: 12 | W4: 14 | X4: 14 | Y4: 16 | Z4: 18 | AA4: 14 | AB4: 16 | AC4: 16 | AD4: 18 | AE4: 14 | AF4: 16 | AG4: 14 | AH4: 16 | AI4: 14 | AJ4: 14 | AK4: 14 | AL4: 16 | AM4: 24 | AN4: 22 | AO4: 22 | AP4: 22 | AQ4: 14 | AR4: 14 | AS4: 12 | AT4: 12 | AU4: 12 | AV4: 12 | AW4: 14 | AX4: 12 | AY4: =SUM(C4:AX4) -> 680
A5: 45507 | B5: 土曜日 | C5: 12 | D5: 12 | E5: 12 | F5: 12 | G5: 12 | H5: 12 | I5: 12 | J5: 12 | K5: 12 | L5: 12 | M5: 12 | N5: 12 | O5: 12 | P5: 12 | Q5: 14 | R5: 12 | S5: 12 | T5: 12 | U5: 14 | V5: 12 | W5: 14 | X5: 12 | Y5: 12 | Z5: 14 | AA5: 14 | AB5: 12 | AC5: 16 | AD5: 14 | AE5: 14 | AF5: 16 | AG5: 16 | AH5: 16 | AI5: 16 | AJ5: 14 | AK5: 16 | AL5: 14 | AM5: 18 | AN5: 18 | AO5: 18 | AP5: 16 | AQ5: 14 | AR5: 14 | AS5: 12 | AT5: 12 | AU5: 12 | AV5: 12 | AW5: 12 | AX5: 12 | AY5: =SUM(C5:AX5) -> 644
A6: 45508 | B6: 日曜日 | C6: 12 | D6: 14 | E6: 10 | F6: 14 | G6: 12 | H6: 12 | I6: 12 | J6: 12 | K6: 12 | L6: 12 | M6: 12 | N6: 12 | O6: 12 | P6: 12 | Q6: 12 | R6: 12 | S6: 12 | T6: 12 | U6: 20 | V6: 18 | W6: 18 | X6: 20 | Y6: 18 | Z6: 20 | AA6: 18 | AB6: 20 | AC6: 14 | AD6: 14 | AE6: 14 | AF6: 14 | AG6: 14 | AH6: 14 | AI6: 14 | AJ6: 14 | AK6: 14 | AL6: 14 | AM6: 18 | AN6: 24 | AO6: 22 | AP6: 18 | AQ6: 18 | AR6: 18 | AS6: 14 | AT6: 12 | AU6: 12 | AV6: 14 | AW6: 12 | AX6: 12 | AY6: =SUM(C6:AX6) -> 704
A7: 45509 | B7: 月曜日 | C7: 12 | D7: 12 | E7: 12 | F7: 12 | G7: 12 | H7: 12 | I7: 12 | J7: 12 | K7: 12 | L7: 12 | M7: 12 | N7: 12 | O7: 12 | P7: 12 | Q7: 12 | R7: 12 | S7: 12 | T7: 12 | U7: 12 | V7: 14 | W7: 12 | X7: 12 | Y7: 12 | Z7: 12 | AA7: 12 | AB7: 12 | AC7: 12 | AD7: 12 | AE7: 12 | AF7: 12 | AG7: 12 | AH7: 12 | AI7: 12 | AJ7: 12 | AK7: 12 | AL7: 12 | AM7: 12 | AN7: 14 | AO7: 12 | AP7: 12 | AQ7: 14 | AR7: 12 | AS7: 12 | AT7: 12 | AU7: 12 | AV7: 12 | AW7: 12 | AX7: 14 | AY7: =SUM(C7:AX7) -> 584
A8: 45510 | B8: 火曜日 | C8: 12 | D8: 12 | E8: 12 | F8: 12 | G8: 12 | H8: 12 | I8: 12 | J8: 12 | K8: 12 | L8: 12 | M8: 12 | N8: 12 | O8: 12 | P8: 12 | Q8: 12 | R8: 12 | S8: 12 | T8: 12 | U8: 20 | V8: 20 | W8: 18 | X8: 14 | Y8: 16 | Z8: 18 | AA8: 16 | AB8: 14 | AC8: 14 | AD8: 20 | AE8: 20 | AF8: 20 | AG8: 24 | AH8: 22 | AI8: 20 | AJ8: 22 | AK8: 20 | AL8: 22 | AM8: 18 | AN8: 20 | AO8: 22 | AP8: 20 | AQ8: 20 | AR8: 18 | AS8: 14 | AT8: 12 | AU8: 12 | AV8: 12 | AW8: 12 | AX8: 14 | AY8: =SUM(C8:AX8) -> 750
A9: 45511 | B9: 水曜日 | C9: 12 | D9: 12 | E9: 12 | F9: 12 | G9: 12 | H9: 12 | I9: 12 | J9: 12 | K9: 12 | L9: 12 | M9: 12 | N9: 14 | O9: 12 | P9: 12 | Q9: 12 | R9: 12 | S9: 12 | T9: 14 | U9: 12 | V9: 14 | W9: 14 | X9: 14 | Y9: 14 | Z9: 14 | AA9: 14 | AB9: 16 | AC9: 16 | AD9: 18 | AE9: 18 | AF9: 18 | AG9: 18 | AH9: 18 | AI9: 20 | AJ9: 18 | AK9: 18 | AL9: 22 | AM9: 20 | AN9: 22 | AO9: 20 | AP9: 22 | AQ9: 20 | AR9: 18 | AS9: 12 | AT9: 12 | AU9: 14 | AV9: 12 | AW9: 12 | AX9: 12 | AY9: =SUM(C9:AX9) -> 712
